Workbook
Name 祷告: _xlfn.ANCHORARRAY(AtkParam!$Y$2)
Name 副手类buff: Buff!$N$2:$N$35
Name 减防debuff: Buff!$J$2:$J$35
Name 立誓类buff: Buff!$L$2:$L$35
Name 魔法: _xlfn.ANCHORARRAY(AtkParam!$X$2)
Name 身体类buff: Buff!$M$2:$M$35
Name 通用buff: Buff!$I$2:$I$35
Name 装备buff: Buff!$K$2:$K$35

Sheet 法术计算器
A1: 艾尔登法环 法术伤害计算器 v1.16 by: 虚空蛋黄酱
A2: 选择人物属性、buff、触媒、敌人、周目数即可直接计算出造成的伤害、削韧、异常值等数据。
A3: 人物属性 | H3: dlc专属 | K3: 敌人属性
A4: 力 | B4: 敏 | C4: 智 | D4: 信 | E4: 感 | F4: 普通石强化 | G4: 失色石强化 | H4: 幽影树庇佑 | I4: 人物加伤 | J4: 人物减伤 | K4: 是否为dlc
A5: 99 | B5: 99 | C5: 99 | D5: 99 | E5: 99 | F5: 25 | G5: 10 | H5: 20 | I5: =HLOOKUP(H5,Curve!B19:V20,2, )-1 -> 1.05 | J5: =1-HLOOKUP(H5,Curve!B19:V21,3, ) -> 0.5121951 | K5: =_xlfn.XLOOKUP(A8,敌人数据!A:A,敌人数据!S:S) -> 否
A6: 敌人属性 | D6: 普通 | E6: 打击 | F6: 斩击 | G6: 突刺 | H6: 魔 | I6: 火 | J6: 雷 | K6: 圣
A7: 敌人 | B7: 周目数 | C7: 防御 | D7: {=IF(LEN(D6:K6),INDEX(敌人数据!C1:J51,MATCH(A8,敌人数据!A1:A51,),MATCH(B8,敌人数据!C1:J1,)))} -> 84 | E7: 84 | F7: 84 | G7: 84 | H7: 84 | I7: 84 | J7: 84 | K7: 84
A8: “结缘牧师”米利耶（壳） | B8: 1 | C8: 伤害倍率 | D8: {=INDEX(敌人数据!K1:R51,MATCH(A8,敌人数据!A1:A51,),)%} -> 0.78 | E8: 1.2 | F8: 0.78 | G8: 1.2 | H8: 1.68 | I8: 2.4 | J8: 1.68 | K8: 1.68
B9: 立誓类buff | C9: 身体类buff | D9: 副手类buff | E9: 装备buff | F9: 减防debuff | G9: 通用buff | H9: 通用buff | I9: 通用buff | J9: 通用buff | K9: 通用buff
A10: buff
A11: 加成1 | B11: {=IF(B10:K10="",1,_xlfn.XLOOKUP(B10:K10,Buff!A:A,Buff!B:B)+1)} -> 1 | C11: 1 | D11: 1 | E11: 1 | F11: 1 | G11: 1 | H11: 1 | I11: 1 | J11: 1 | K11: 1
A12: 限定1 | B12: {=IF(B10:K10="","",_xlfn.XLOOKUP(B10:K10,Buff!A:A,Buff!C:C))}
A13: 加成2 | B13: {=IF(B10:K10="",1,_xlfn.XLOOKUP(B10:K10,Buff!A:A,Buff!D:D)+1)} -> 1 | C13: 1 | D13: 1 | E13: 1 | F13: 1 | G13: 1 | H13: 1 | I13: 1 | J13: 1 | K13: 1
A14: 限定2 | B14: {=IF(B10:K10="","",_xlfn.XLOOKUP(B10:K10,Buff!A:A,Buff!E:E))}
A16: 类型 | B16: 法术 | C16: 触媒 | D16: 总伤害 | E16: 伤害类型 | F16: 基础值 | G16: 特殊类型 | H16: 一周目削韧 | I16: ="当前周目"&CHAR(10)&TEXT(B8,"[DBNum1]")&"周目削韧" -> 当前周目 一周目削韧 | J16: 冲击力 | K16: 异常值 | L16: 法术列表 | M16: 触媒列表 | N16: 失色石 | O16: 强化等级 | P16: 强化曲线 | Q16: 物基础 | R16: 魔基础 | S16: 火基础 | T16: 雷基础 | U16: 圣基础 | V16: 力补正 | W16: 敏补正 | X16: 智补正 | Y16: 信补正 | Z16: 感补正 | AA16: 物成长 | AB16: 魔成长 | AC16: 火成长 | AD16: 雷成长 | AE16: 圣成长 | AF16: 力补正成长 | AG16: 敏补正成长 | AH16: 智补正成长 | AI16: 信补正成长 | AJ16: 感补正成长 | AK16: 补正修正 | AL16: 力补物 | AM16: 敏补物 | AN16: 智补物 | AO16: 信补物 | AP16: 感补物 | AQ16: 力补魔 | AR16: 敏补魔 | AS16: 智补魔 | AT16: 信补魔 | AU16: 感补魔 | AV16: 力补火 | AW16: 敏补火 | AX16: 智补火 | AY16: 信补火 | AZ16: 感补火 | BA16: 力补雷 | BB16: 敏补雷 | BC16: 智补雷 | BD16: 信补雷 | BE16: 感补雷 | BF16: 力补圣 | BG16: 敏补圣 | BH16: 智补圣 | BI16: 信补圣 | BJ16: 感补圣 | BK16: 物攻击力 | BL16: 魔攻击力 | BM16: 火攻击力 | BN16: 雷攻击力 | BO16: 圣攻击力 | BP16: 物理属性 | BQ16: 特殊类型1 | BR16: 特殊类型2 | BS16: 特殊类型3 | BT16: 触媒加成 | BU16: 触媒属性 | BV16: 通用buff | BW16: 物buff | BX16: 魔buff | BY16: 火buff | BZ16: 雷buff | CA16: 圣buff | CB16: 物伤害 | CC16: 魔伤害 | CD16: 火伤害 | CE16: 雷伤害 | CF16: 圣伤害 | CG16: 异常 | CH16: 异常属性 | CI16: 异常补正 | CJ16: 异常是否补正 | CK16: 血焰 | CL16: 基础耗精 | CM16: 耗精倍率
A17: 魔法 | B17: 帚星 | C17: 母亲杖 | D17: {=_xlfn.BYROW(_xlfn.ANCHORARRAY(CB17):_xlfn.ANCHORARRAY(CF17),_xlfn.LAMBDA(_xlpm.x,INT(SUM(_xlpm.x))))} -> 1898 | E17: {=_xlfn.BYROW(IF(_xlfn.ANCHORARRAY(CB17):_xlfn.ANCHORARRAY(CF17),IF({1,0,0,0,0},_xlfn.ANCHORARRAY(BP17),LEFT(CB16:CF16)),""),_xlfn.LAMBDA(_xlpm.x,_xlfn.TEXTJOIN("+",,_xlpm.x)))} -> 魔 | F17: {=_xlfn.BYROW(_xlfn.ANCHORARRAY(Q17):_xlfn.ANCHORARRAY(U17),_xlfn.LAMBDA(_xlpm.x,_xlfn.TEXTJOIN("+",,IF(_xlpm.x,_xlpm.x,""))))} -> 292 | G17: {=_xlfn.BYROW(_xlfn.ANCHORARRAY(BQ17):_xlfn.ANCHORARRAY(BS17),_xlfn.LAMBDA(_xlpm.x,_xlfn.TEXTJOIN(",",,IF(_xlpm.x="无","",_xlpm.x))))} -> 亚兹勒1 | H17: {=ROUND(_xlfn.XLOOKUP(_xlfn.ANCHORARRAY(L17),AtkParam!B:B,AtkParam!R:R),2)} -> 7 | I17: {=_xlfn.ANCHORARRAY(H17)*INDEX({1,1,0.95,0.9,0.85,0.8,0.7,0.6},B8)} -> 7 | J17: {=_xlfn.XLOOKUP(_xlfn.XLOOKUP(_xlfn.ANCHORARRAY(L17),AtkParam!B:B,AtkParam!S:S),List!A2:A13,List!B2:B13)} -> 1（小硬直） | K17: {=_xlfn.LET(_xlpm.p,_xlfn.ANCHORARRAY(CG17)*(1+_xlfn.ANCHORARRAY(CJ17)*_xlfn.ANCHORARRAY(Z17)%*INDEX(Curve!B2:EU18,_xlfn.ANCHORARRAY(CI17)+1,E5)%*_xlfn.ANCHORARRAY(AJ17)),_xlfn.IFS(_xlfn.ANCHORARRAY(CK17),_xlfn.ANCHORARRAY(CK17)&"出血值",_xlpm.p,INT(_xlpm.p)&_xlfn.ANCHORARRAY(CH17),1,"无"))} -> 无 | L17: {=_xlfn.TOCOL(B17:B99,3)} -> 帚星 | M17: {=_xlfn.TOCOL(C17:C99,3)} -> 母亲杖 | N17: {=IF(_xlfn.XLOOKUP(_xlfn.ANCHORARRAY(M17),Weapon!B:B,Weapon!G:G),"失色石","普通石")} -> 普通石 | O17: {=_xlfn.IFS(_xlfn.ANCHORARRAY(M17)="陨石杖",,_xlfn.ANCHORARRAY(N17)="失色石",G5,1,F5)} -> 25 | P17: {=_xlfn.XLOOKUP(_xlfn.ANCHORARRAY(M17),Weapon!B:B,Weapon!H:H)+_xlfn.ANCHORARRAY(O17)} -> 1925 | Q17: {=_xlfn.XLOOKUP(_xlfn.TOCOL($B$17:$B$99,3),AtkParam!$B:$B,AtkParam!G:G)} -> 0 | R17: {=_xlfn.XLOOKUP(_xlfn.TOCOL($B$17:$B$99,3),AtkParam!$B:$B,AtkParam!H:H)} -> 292 | S17: {=_xlfn.XLOOKUP(_xlfn.TOCOL($B$17:$B$99,3),AtkParam!$B:$B,AtkParam!I:I)} -> 0 | T17: {=_xlfn.XLOOKUP(_xlfn.TOCOL($B$17:$B$99,3),AtkParam!$B:$B,AtkParam!J:J)} -> 0 | U17: {=_xlfn.XLOOKUP(_xlfn.TOCOL($B$17:$B$99,3),AtkParam!$B:$B,AtkParam!K:K)} -> 0 | V17: {=_xlfn.XLOOKUP(_xlfn.TOCOL($C$17:$C$99,3),Weapon!$B:$B,Weapon!I:I)} -> 12 | W17: {=_xlfn.XLOOKUP(_xlfn.TOCOL($C$17:$C$99,3),Weapon!$B:$B,Weapon!J:J)} -> 0 | X17: {=_xlfn.XLOOKUP(_xlfn.TOCOL($C$17:$C$99,3),Weapon!$B:$B,Weapon!K:K)} -> 55 | Y17: {=_xlfn.XLOOKUP(_xlfn.TOCOL($C$17:$C$99,3),Weapon!$B:$B,Weapon!L:L)} -> 0 | Z17: {=_xlfn.XLOOKUP(_xlfn.TOCOL($C$17:$C$99,3),Weapon!$B:$B,Weapon!M:M)} -> 55 | AA17: {=_xlfn.XLOOKUP(_xlfn.ANCHORARRAY($M$17),Weapon!$B:$B,Weapon!N:N)} -> 15 | AB17: {=_xlfn.XLOOKUP(_xlfn.ANCHORARRAY($M$17),Weapon!$B:$B,Weapon!O:O)} -> 15 | AC17: {=_xlfn.XLOOKUP(_xlfn.ANCHORARRAY($M$17),Weapon!$B:$B,Weapon!P:P)} -> 15 | AD17: {=_xlfn.XLOOKUP(_xlfn.ANCHORARRAY($M$17),Weapon!$B:$B,Weapon!Q:Q)} -> 15 | AE17: {=_xlfn.XLOOKUP(_xlfn.ANCHORARRAY($M$17),Weapon!$B:$B,Weapon!R:R)} -> 15 | AF17: {=_xlfn.XLOOKUP(_xlfn.ANCHORARRAY($P$17),WeaponUP!$A:$A,WeaponUP!B:B)} -> 3 | AG17: {=_xlfn.XLOOKUP(_xlfn.ANCHORARRAY($P$17),WeaponUP!$A:$A,WeaponUP!C:C)} -> 3 | AH17: {=_xlfn.XLOOKUP(_xlfn.ANCHORARRAY($P$17),WeaponUP!$A:$A,WeaponUP!D:D)} -> 3 | AI17: {=_xlfn.XLOOKUP(_xlfn.ANCHORARRAY($P$17),WeaponUP!$A:$A,WeaponUP!E:E)} -> 3 | AJ17: {=_xlfn.XLOOKUP(_xlfn.ANCHORARRAY($P$17),WeaponUP!$A:$A,WeaponUP!F:F)} -> 3 | AK17: {=_xlfn.XLOOKUP(_xlfn.TOCOL($C$17:$C$99,3),Weapon!$B:$B,Weapon!T:T)} -> 20030 | AL17: {=_xlfn.XLOOKUP(_xlfn.ANCHORARRAY($AK$17),AtkCorrect!$A:$A,AtkCorrect!B:B)*INDEX(Curve!$B$2:$EU$18,_xlfn.ANCHORARRAY($AA$17)+1,A5)%*_xlfn.ANCHORARRAY(V17)%*_xlfn.ANCHORARRAY(AF17)} -> 0 | AM17: {=_xlfn.XLOOKUP(_xlfn.ANCHORARRAY($AK$17),AtkCorrect!$A:$A,AtkCorrect!C:C)*INDEX(Curve!$B$2:$EU$18,_xlfn.ANCHORARRAY($AA$17)+1,B5)%*_xlfn.ANCHORARRAY(W17)%*_xlfn.ANCHORARRAY(AG17)} -> 0 | AN17: {=_xlfn.XLOOKUP(_xlfn.ANCHORARRAY($AK$17),AtkCorrect!$A:$A,AtkCorrect!D:D)*INDEX(Curve!$B$2:$EU$18,_xlfn.ANCHORARRAY($AA$17)+1,C5)%*_xlfn.ANCHORARRAY(X17)%*_xlfn.ANCHORARRAY(AH17)} -> 1.65 | AO17: {=_xlfn.XLOOKUP(_xlfn.ANCHORARRAY($AK$17),AtkCorrect!$A:$A,AtkCorrect!E:E)*INDEX(Curve!$B$2:$EU$18,_xlfn.ANCHORARRAY($AA$17)+1,D5)%*_xlfn.ANCHORARRAY(Y17)%*_xlfn.ANCHORARRAY(AI17)} -> 0 | AP17: {=_xlfn.XLOOKUP(_xlfn.ANCHORARRAY($AK$17),AtkCorrect!$A:$A,AtkCorrect!F:F)*INDEX(Curve!$B$2:$EU$18,_xlfn.ANCHORARRAY($AA$17)+1,E5)%*_xlfn.ANCHORARRAY(Z17)%*_xlfn.ANCHORARRAY(AJ17)} -> 1.65 | AQ17: {=_xlfn.XLOOKUP(_xlfn.ANCHORARRAY($AK$17),AtkCorrect!$A:$A,AtkCorrect!G:G)*INDEX(Curve!$B$2:$EU$18,_xlfn.ANCHORARRAY($AB$17)+1,A5)%*_xlfn.ANCHORARRAY(V17)%*_xlfn.ANCHORARRAY(AF17)} -> 0 | AR17: {=_xlfn.XLOOKUP(_xlfn.ANCHORARRAY($AK$17),AtkCorrect!$A:$A,AtkCorrect!H:H)*INDEX(Curve!$B$2:$EU$18,_xlfn.ANCHORARRAY($AB$17)+1,B5)%*_xlfn.ANCHORARRAY(W17)%*_xlfn.ANCHORARRAY(AG17)} -> 0 | AS17: {=_xlfn.XLOOKUP(_xlfn.ANCHORARRAY($AK$17),AtkCorrect!$A:$A,AtkCorrect!I:I)*INDEX(Curve!$B$2:$EU$18,_xlfn.ANCHORARRAY($AB$17)+1,C5)%*_xlfn.ANCHORARRAY(X17)%*_xlfn.ANCHORARRAY(AH17)} -> 1.65 | AT17: {=_xlfn.XLOOKUP(_xlfn.ANCHORARRAY($AK$17),AtkCorrect!$A:$A,AtkCorrect!J:J)*INDEX(Curve!$B$2:$EU$18,_xlfn.ANCHORARRAY($AB$17)+1,D5)%*_xlfn.ANCHORARRAY(Y17)%*_xlfn.ANCHORARRAY(AI17)} -> 0 | AU17: {=_xlfn.XLOOKUP(_xlfn.ANCHORARRAY($AK$17),AtkCorrect!$A:$A,AtkCorrect!K:K)*INDEX(Curve!$B$2:$EU$18,_xlfn.ANCHORARRAY($AB$17)+1,E5)%*_xlfn.ANCHORARRAY(Z17)%*_xlfn.ANCHORARRAY(AJ17)} -> 1.65 | AV17: {=_xlfn.XLOOKUP(_xlfn.ANCHORARRAY($AK$17),AtkCorrect!$A:$A,AtkCorrect!L:L)*INDEX(Curve!$B$2:$EU$18,_xlfn.ANCHORARRAY($AC$17)+1,A5)%*_xlfn.ANCHORARRAY(V17)%*_xlfn.ANCHORARRAY(AF17)} -> 0 | AW17: {=_xlfn.XLOOKUP(_xlfn.ANCHORARRAY($AK$17),AtkCorrect!$A:$A,AtkCorrect!M:M)*INDEX(Curve!$B$2:$EU$18,_xlfn.ANCHORARRAY($AC$17)+1,B5)%*_xlfn.ANCHORARRAY(W17)%*_xlfn.ANCHORARRAY(AG17)} -> 0 | AX17: {=_xlfn.XLOOKUP(_xlfn.ANCHORARRAY($AK$17),AtkCorrect!$A:$A,AtkCorrect!N:N)*INDEX(Curve!$B$2:$EU$18,_xlfn.ANCHORARRAY($AC$17)+1,C5)%*_xlfn.ANCHORARRAY(X17)%*_xlfn.ANCHORARRAY(AH17)} -> 1.65 | AY17: {=_xlfn.XLOOKUP(_xlfn.ANCHORARRAY($AK$17),AtkCorrect!$A:$A,AtkCorrect!O:O)*INDEX(Curve!$B$2:$EU$18,_xlfn.ANCHORARRAY($AC$17)+1,D5)%*_xlfn.ANCHORARRAY(Y17)%*_xlfn.ANCHORARRAY(AI17)} -> 0 | AZ17: {=_xlfn.XLOOKUP(_xlfn.ANCHORARRAY($AK$17),AtkCorrect!$A:$A,AtkCorrect!P:P)*INDEX(Curve!$B$2:$EU$18,_xlfn.ANCHORARRAY($AC$17)+1,E5)%*_xlfn.ANCHORARRAY(Z17)%*_xlfn.ANCHORARRAY(AJ17)} -> 1.65 | BA17: {=_xlfn.XLOOKUP(_xlfn.ANCHORARRAY($AK$17),AtkCorrect!$A:$A,AtkCorrect!Q:Q)*INDEX(Curve!$B$2:$EU$18,_xlfn.ANCHORARRAY($AD$17)+1,A5)%*_xlfn.ANCHORARRAY(V17)%*_xlfn.ANCHORARRAY(AF17)} -> 0 | BB17: {=_xlfn.XLOOKUP(_xlfn.ANCHORARRAY($AK$17),AtkCorrect!$A:$A,AtkCorrect!R:R)*INDEX(Curve!$B$2:$EU$18,_xlfn.ANCHORARRAY($AD$17)+1,B5)%*_xlfn.ANCHORARRAY(W17)%*_xlfn.ANCHORARRAY(AG17)} -> 0 | BC17: {=_xlfn.XLOOKUP(_xlfn.ANCHORARRAY($AK$17),AtkCorrect!$A:$A,AtkCorrect!S:S)*INDEX(Curve!$B$2:$EU$18,_xlfn.ANCHORARRAY($AD$17)+1,C5)%*_xlfn.ANCHORARRAY(X17)%*_xlfn.ANCHORARRAY(AH17)} -> 1.65 | BD17: {=_xlfn.XLOOKUP(_xlfn.ANCHORARRAY($AK$17),AtkCorrect!$A:$A,AtkCorrect!T:T)*INDEX(Curve!$B$2:$EU$18,_xlfn.ANCHORARRAY($AD$17)+1,D5)%*_xlfn.ANCHORARRAY(Y17)%*_xlfn.ANCHORARRAY(AI17)} -> 0 | BE17: {=_xlfn.XLOOKUP(_xlfn.ANCHORARRAY($AK$17),AtkCorrect!$A:$A,AtkCorrect!U:U)*INDEX(Curve!$B$2:$EU$18,_xlfn.ANCHORARRAY($AD$17)+1,E5)%*_xlfn.ANCHORARRAY(Z17)%*_xlfn.ANCHORARRAY(AJ17)} -> 1.65 | BF17: {=_xlfn.XLOOKUP(_xlfn.ANCHORARRAY($AK$17),AtkCorrect!$A:$A,AtkCorrect!V:V)*INDEX(Curve!$B$2:$EU$18,_xlfn.ANCHORARRAY($AE$17)+1,A5)%*_xlfn.ANCHORARRAY(V17)%*_xlfn.ANCHORARRAY(AF17)} -> 0 | BG17: {=_xlfn.XLOOKUP(_xlfn.ANCHORARRAY($AK$17),AtkCorrect!$A:$A,AtkCorrect!W:W)*INDEX(Curve!$B$2:$EU$18,_xlfn.ANCHORARRAY($AE$17)+1,B5)%*_xlfn.ANCHORARRAY(W17)%*_xlfn.ANCHORARRAY(AG17)} -> 0 | BH17: {=_xlfn.XLOOKUP(_xlfn.ANCHORARRAY($AK$17),AtkCorrect!$A:$A,AtkCorrect!X:X)*INDEX(Curve!$B$2:$EU$18,_xlfn.ANCHORARRAY($AE$17)+1,C5)%*_xlfn.ANCHORARRAY(X17)%*_xlfn.ANCHORARRAY(AH17)} -> 1.65 | BI17: {=_xlfn.XLOOKUP(_xlfn.ANCHORARRAY($AK$17),AtkCorrect!$A:$A,AtkCorrect!Y:Y)*INDEX(Curve!$B$2:$EU$18,_xlfn.ANCHORARRAY($AE$17)+1,D5)%*_xlfn.ANCHORARRAY(Y17)%*_xlfn.ANCHORARRAY(AI17)} -> 0 | BJ17: {=_xlfn.XLOOKUP(_xlfn.ANCHORARRAY($AK$17),AtkCorrect!$A:$A,AtkCorrect!Z:Z)*INDEX(Curve!$B$2:$EU$18,_xlfn.ANCHORARRAY($AE$17)+1,E5)%*_xlfn.ANCHORARRAY(Z17)%*_xlfn.ANCHORARRAY(AJ17)} -> 1.65 | BK17: {=_xlfn.ANCHORARRAY(Q17)*(1+_xlfn.BYROW(_xlfn.ANCHORARRAY(AL17):_xlfn.ANCHORARRAY(AP17),_xleta.SUM))} -> 0 | BL17: {=_xlfn.ANCHORARRAY(R17)*(1+_xlfn.BYROW(_xlfn.ANCHORARRAY(AQ17):_xlfn.ANCHORARRAY(AU17),_xleta.SUM))} -> 1255.6 | BM17: {=_xlfn.ANCHORARRAY(S17)*(1+_xlfn.BYROW(_xlfn.ANCHORARRAY(AV17):_xlfn.ANCHORARRAY(AZ17),_xleta.SUM))} -> 0 | BN17: {=_xlfn.ANCHORARRAY(T17)*(1+_xlfn.BYROW(_xlfn.ANCHORARRAY(BA17):_xlfn.ANCHORARRAY(BE17),_xleta.SUM))} -> 0 | BO17: {=_xlfn.ANCHORARRAY(U17)*(1+_xlfn.BYROW(_xlfn.ANCHORARRAY(BF17):_xlfn.ANCHORARRAY(BJ17),_xleta.SUM))} -> 0 | BP17: {=_xlfn.XLOOKUP(_xlfn.TOCOL($B$17:$B$99,3),AtkParam!$B:$B,AtkParam!L:L)} -> 无 | BQ17: {=_xlfn.XLOOKUP(_xlfn.TOCOL($B$17:$B$99,3),AtkParam!$B:$B,AtkParam!M:M)} -> 亚兹勒1 | BR17: {=_xlfn.XLOOKUP(_xlfn.TOCOL($B$17:$B$99,3),AtkParam!$B:$B,AtkParam!N:N)} -> 无 | BS17: {=_xlfn.XLOOKUP(_xlfn.TOCOL($B$17:$B$99,3),AtkParam!$B:$B,AtkParam!O:O)} -> 无 | BT17: {=IF((_xlfn.ANCHORARRAY(BU17)=_xlfn.ANCHORARRAY(BQ17))+(_xlfn.ANCHORARRAY(BU17)=_xlfn.ANCHORARRAY(BR17))+(_xlfn.ANCHORARRAY(BU17)=_xlfn.ANCHORARRAY(BS17)),_xlfn.XLOOKUP(_xlfn.ANCHORARRAY(M17),Weapon!$B:$B,Weapon!V:V),1)} -> 1 | BU17: {=_xlfn.XLOOKUP(_xlfn.TOCOL($C$17:$C$99,3),Weapon!$B:$B,Weapon!W:W)} -> 指头 | BV17: {=_xlfn.BYROW(IF(_xlfn.ANCHORARRAY(B12)="全",_xlfn.ANCHORARRAY(B11),1)*IF(_xlfn.ANCHORARRAY(BQ17)=_xlfn.ANCHORARRAY(B12),_xlfn.ANCHORARRAY(B11),1)*IF(_xlfn.ANCHORARRAY(BQ17)=_xlfn.ANCHORARRAY(B14),_xlfn.ANCHORARRAY(B13),1)*IF(_xlfn.ANCHORARRAY(BR17)=_xlfn.ANCHORARRAY(B12),_xlfn.ANCHORARRAY(B11),1)*IF(_xlfn.ANCHORARRAY(BS17)=_xlfn.ANCHORARRAY(B12),_xlfn.ANCHORARRAY(B11),1),_xlfn.LAMBDA(_xlpm.x,PRODUCT(_xlpm.x)))*IF(K5="是",I5+1,1)*IF(_xlfn.BYROW(N(_xlfn.ANCHORARRAY(BQ17):_xlfn.ANCHORARRAY(BS17)=_xlfn.ANCHORARRAY(BU17)),_xleta.SUM),_xlfn.ANCHORARRAY(BT17),1)} -> 1 | BW17: {=IF(_xlfn.ANCHORARRAY($BV$17),PRODUCT(IF(_xlfn.ANCHORARRAY($B$12)="物",_xlfn.ANCHORARRAY($B$11),1)*IF(_xlfn.ANCHORARRAY($B$14)="物",_xlfn.ANCHORARRAY($B$13),1)))} -> 1 | BX17: {=IF(_xlfn.ANCHORARRAY($BV$17),PRODUCT(IF(_xlfn.ANCHORARRAY($B$12)="魔",_xlfn.ANCHORARRAY($B$11),1)*IF(_xlfn.ANCHORARRAY($B$14)="魔",_xlfn.ANCHORARRAY($B$13),1)))} -> 1 | BY17: {=IF(_xlfn.ANCHORARRAY($BV$17),PRODUCT(IF(_xlfn.ANCHORARRAY($B$12)="火",_xlfn.ANCHORARRAY($B$11),1)*IF(_xlfn.ANCHORARRAY($B$14)="火",_xlfn.ANCHORARRAY($B$13),1)))} -> 1 | BZ17: {=IF(_xlfn.ANCHORARRAY($BV$17),PRODUCT(IF(_xlfn.ANCHORARRAY($B$12)="雷",_xlfn.ANCHORARRAY($B$11),1)*IF(_xlfn.ANCHORARRAY($B$14)="雷",_xlfn.ANCHORARRAY($B$13),1)))} -> 1 | CA17: {=IF(_xlfn.ANCHORARRAY($BV$17),PRODUCT(IF(_xlfn.ANCHORARRAY($B$12)="圣",_xlfn.ANCHORARRAY($B$11),1)*IF(_xlfn.ANCHORARRAY($B$14)="圣",_xlfn.ANCHORARRAY($B$13),1)))} -> 1 | CB17: {=_xlfn.LET(_xlpm.r,_xlfn.XLOOKUP(_xlfn.ANCHORARRAY(BP17),D6:G6,D8:G8,0),_xlpm.p,_xlfn.ANCHORARRAY(BK17)/G7,_xlpm.q,MATCH(_xlpm.p,List!$C$2:$C$6),_xlpm.a,INDEX(List!$D$2:$D$6,_xlpm.q),_xlpm.b,INDEX(List!$E$2:$E$6,_xlpm.q),_xlpm.c,INDEX(List!$F$2:$F$6,_xlpm.q),(_xlpm.a*(_xlpm.p-_xlpm.b)^2+_xlpm.c)*_xlfn.ANCHORARRAY(BK17)*_xlfn.ANCHORARRAY($BV$17)*_xlfn.ANCHORARRAY(BW17)*_xlpm.r)} -> 0 | CC17: {=_xlfn.LET(_xlpm.r,H8,_xlpm.p,_xlfn.ANCHORARRAY(BL17)/H7,_xlpm.q,MATCH(_xlpm.p,List!$C$2:$C$6),_xlpm.a,INDEX(List!$D$2:$D$6,_xlpm.q),_xlpm.b,INDEX(List!$E$2:$E$6,_xlpm.q),_xlpm.c,INDEX(List!$F$2:$F$6,_xlpm.q),(_xlpm.a*(_xlpm.p-_xlpm.b)^2+_xlpm.c)*_xlfn.ANCHORARRAY(BL17)*_xlfn.ANCHORARRAY($BV$17)*_xlfn.ANCHORARRAY(BX17)*_xlpm.r)} -> 1898.4672 | CD17: {=_xlfn.LET(_xlpm.r,I8,_xlpm.p,_xlfn.ANCHORARRAY(BM17)/I7,_xlpm.q,MATCH(_xlpm.p,List!$C$2:$C$6),_xlpm.a,INDEX(List!$D$2:$D$6,_xlpm.q),_xlpm.b,INDEX(List!$E$2:$E$6,_xlpm.q),_xlpm.c,INDEX(List!$F$2:$F$6,_xlpm.q),(_xlpm.a*(_xlpm.p-_xlpm.b)^2+_xlpm.c)*_xlfn.ANCHORARRAY(BM17)*_xlfn.ANCHORARRAY($BV$17)*_xlfn.ANCHORARRAY(BY17)*_xlpm.r)} -> 0 | CE17: {=_xlfn.LET(_xlpm.r,J8,_xlpm.p,_xlfn.ANCHORARRAY(BN17)/J7,_xlpm.q,MATCH(_xlpm.p,List!$C$2:$C$6),_xlpm.a,INDEX(List!$D$2:$D$6,_xlpm.q),_xlpm.b,INDEX(List!$E$2:$E$6,_xlpm.q),_xlpm.c,INDEX(List!$F$2:$F$6,_xlpm.q),(_xlpm.a*(_xlpm.p-_xlpm.b)^2+_xlpm.c)*_xlfn.ANCHORARRAY(BN17)*_xlfn.ANCHORARRAY($BV$17)*_xlfn.ANCHORARRAY(BZ17)*_xlpm.r)} -> 0 | CF17: {=_xlfn.LET(_xlpm.r,K8,_xlpm.p,_xlfn.ANCHORARRAY(BO17)/K7,_xlpm.q,MATCH(_xlpm.p,List!$C$2:$C$6),_xlpm.a,INDEX(List!$D$2:$D$6,_xlpm.q),_xlpm.b,INDEX(List!$E$2:$E$6,_xlpm.q),_xlpm.c,INDEX(List!$F$2:$F$6,_xlpm.q),(_xlpm.a*(_xlpm.p-_xlpm.b)^2+_xlpm.c)*_xlfn.ANCHORARRAY(BO17)*_xlfn.ANCHORARRAY($BV$17)*_xlfn.ANCHORARRAY(CA17)*_xlpm.r)} -> 0 | CG17: {=_xlfn.XLOOKUP(_xlfn.TOCOL($B$17:$B$99,3),AtkParam!$B:$B,AtkParam!T:T)} -> 0 | CH17: {=_xlfn.XLOOKUP(_xlfn.TOCOL($B$17:$B$99,3),AtkParam!$B:$B,AtkParam!U:U)&""} | CI17: {=_xlfn.XLOOKUP(_xlfn.ANCHORARRAY(M17),Weapon!B:B,Weapon!S:S)} -> 6 | CJ17: {=_xlfn.XLOOKUP(_xlfn.ANCHORARRAY(L17),AtkParam!B:B,AtkParam!V:V)} -> 0 | CK17: {=_xlfn.XLOOKUP(_xlfn.ANCHORARRAY(L17),AtkParam!B:B,AtkParam!W:W)} -> 0 | CL17: {=_xlfn.XLOOKUP(_xlfn.ANCHORARRAY(L17),AtkParam!B:B,AtkParam!Q:Q)} -> 24 | CM17: {=_xlfn.XLOOKUP(_xlfn.ANCHORARRAY(M17),Weapon!B:B,Weapon!U:U)} -> 1.03
A18: 魔法 | B18: 拉卡德的怨魂 | C18: 母亲杖 | D18: 1392 | E18: 火 | F18: 150 | G18: 格密尔 | H18: 5 | I18: 5 | J18: 2（中硬直） | K18: 无 | L18: 拉卡德的怨魂 | M18: 母亲杖 | N18: 普通石 | O18: 25 | P18: 1925 | Q18: 0 | R18: 0 | S18: 150 | T18: 0 | U18: 0 | V18: 12 | W18: 0 | X18: 55 | Y18: 0 | Z18: 55 | AA18: 15 | AB18: 15 | AC18: 15 | AD18: 15 | AE18: 15 | AF18: 3 | AG18: 3 | AH18: 3 | AI18: 3 | AJ18: 3 | AK18: 20030 | AL18: 0 | AM18: 0 | AN18: 1.65 | AO18: 0 | AP18: 1.65 | AQ18: 0 | AR18: 0 | AS18: 1.65 | AT18: 0 | AU18: 1.65 | AV18: 0 | AW18: 0 | AX18: 1.65 | AY18: 0 | AZ18: 1.65 | BA18: 0 | BB18: 0 | BC18: 1.65 | BD18: 0 | BE18: 1.65 | BF18: 0 | BG18: 0 | BH18: 1.65 | BI18: 0 | BJ18: 1.65 | BK18: 0 | BL18: 0 | BM18: 645 | BN18: 0 | BO18: 0 | BP18: 无 | BQ18: 格密尔 | BR18: 无 | BS18: 无 | BT18: 1 | BU18: 指头 | BV18: 1 | BW18: 1 | BX18: 1 | BY18: 1 | BZ18: 1 | CA18: 1 | CB18: 0 | CC18: 0 | CD18: 1392.1426 | CE18: 0 | CF18: 0 | CG18: 0 | CI18: 6 | CJ18: 0 | CK18: 0 | CL18: 23 | CM18: 1.03
A19: 魔法 | B19: 艾丝缇陨石 | C19: 母亲杖 | D19: 1206 | E19: 普通+魔 | F19: 185+105 | G19: 重力 | H19: 10.18 | I19: 10.18 | J19: 7（击退） | K19: 无 | L19: 艾丝缇陨石 | M19: 母亲杖 | N19: 普通石 | O19: 25 | P19: 1925 | Q19: 185 | R19: 105 | S19: 0 | T19: 0 | U19: 0 | V19: 12 | W19: 0 | X19: 55 | Y19: 0 | Z19: 55 | AA19: 15 | AB19: 15 | AC19: 15 | AD19: 15 | AE19: 15 | AF19: 3 | AG19: 3 | AH19: 3 | AI19: 3 | AJ19: 3 | AK19: 20030 | AL19: 0 | AM19: 0 | AN19: 1.65 | AO19: 0 | AP19: 1.65 | AQ19: 0 | AR19: 0 | AS19: 1.65 | AT19: 0 | AU19: 1.65 | AV19: 0 | AW19: 0 | AX19: 1.65 | AY19: 0 | AZ19: 1.65 | BA19: 0 | BB19: 0 | BC19: 1.65 | BD19: 0 | BE19: 1.65 | BF19: 0 | BG19: 0 | BH19: 1.65 | BI19: 0 | BJ19: 1.65 | BK19: 795.5 | BL19: 451.5 | BM19: 0 | BN19: 0 | BO19: 0 | BP19: 普通 | BQ19: 重力 | BR19: 无 | BS19: 无 | BT19: 1 | BU19: 指头 | BV19: 1 | BW19: 1 | BX19: 1 | BY19: 1 | BZ19: 1 | CA19: 1 | CB19: 558.441 | CC19: 648.11146 | CD19: 0 | CE19: 0 | CF19: 0 | CG19: 0 | CI19: 6 | CJ19: 0 | CK19: 0 | CL19: 60 | CM19: 1.03
A20: 魔法 | B20: 熔岩球 | C20: 母亲杖 | D20: 1950 | E20: 火 | F20: 210 | G20: 格密尔,熔岩 | H20: 5 | I20: 5 | J20: 3（大硬直） | K20: 无 | L20: 熔岩球 | M20: 母亲杖 | N20: 普通石 | O20: 25 | P20: 1925 | Q20: 0 | R20: 0 | S20: 210 | T20: 0 | U20: 0 | V20: 12 | W20: 0 | X20: 55 | Y20: 0 | Z20: 55 | AA20: 15 | AB20: 15 | AC20: 15 | AD20: 15 | AE20: 15 | AF20: 3 | AG20: 3 | AH20: 3 | AI20: 3 | AJ20: 3 | AK20: 20030 | AL20: 0 | AM20: 0 | AN20: 1.65 | AO20: 0 | AP20: 1.65 | AQ20: 0 | AR20: 0 | AS20: 1.65 | AT20: 0 | AU20: 1.65 | AV20: 0 | AW20: 0 | AX20: 1.65 | AY20: 0 | AZ20: 1.65 | BA20: 0 | BB20: 0 | BC20: 1.65 | BD20: 0 | BE20: 1.65 | BF20: 0 | BG20: 0 | BH20: 1.65 | BI20: 0 | BJ20: 1.65 | BK20: 0 | BL20: 0 | BM20: 903 | BN20: 0 | BO20: 0 | BP20: 无 | BQ20: 格密尔 | BR20: 无 | BS20: 熔岩 | BT20: 1 | BU20: 指头 | BV20: 1 | BW20: 1 | BX20: 1 | BY20: 1 | BZ20: 1 | CA20: 1 | CB20: 0 | CC20: 0 | CD20: 1950.48 | CE20: 0 | CF20: 0 | CG20: 0 | CI20: 6 | CJ20: 0 | CK20: 0 | CL20: 16 | CM20: 1.03
A21: 魔法 | B21: 岩石球 | C21: 母亲杖 | D21: 290 | E21: 普通 | F21: 102 | G21: 重力 | H21: 9.5 | I21: 9.5 | J21: 2（中硬直） | K21: 无 | L21: 岩石球 | M21: 母亲杖 | N21: 普通石 | O21: 25 | P21: 1925 | Q21: 102 | R21: 0 | S21: 0 | T21: 0 | U21: 0 | V21: 12 | W21: 0 | X21: 55 | Y21: 0 | Z21: 55 | AA21: 15 | AB21: 15 | AC21: 15 | AD21: 15 | AE21: 15 | AF21: 3 | AG21: 3 | AH21: 3 | AI21: 3 | AJ21: 3 | AK21: 20030 | AL21: 0 | AM21: 0 | AN21: 1.65 | AO21: 0 | AP21: 1.65 | AQ21: 0 | AR21: 0 | AS21: 1.65 | AT21: 0 | AU21: 1.65 | AV21: 0 | AW21: 0 | AX21: 1.65 | AY21: 0 | AZ21: 1.65 | BA21: 0 | BB21: 0 | BC21: 1.65 | BD21: 0 | BE21: 1.65 | BF21: 0 | BG21: 0 | BH21: 1.65 | BI21: 0 | BJ21: 1.65 | BK21: 438.6 | BL21: 0 | BM21: 0 | BN21: 0 | BO21: 0 | BP21: 普通 | BQ21: 重力 | BR21: 无 | BS21: 无 | BT21: 1 | BU21: 指头 | BV21: 1 | BW21: 1 | BX21: 1 | BY21: 1 | BZ21: 1 | CA21: 1 | CB21: 290.43452 | CC21: 0 | CD21: 0 | CE21: 0 | CF21: 0 | CG21: 0 | CI21: 6 | CJ21: 0 | CK21: 0 | CL21: 18 | CM21: 1.03
A22: 魔法 | B22: 帚星 | C22: 母亲杖 | D22: 1898 | E22: 魔 | F22: 292 | G22: 亚兹勒1 | H22: 7 | I22: 7 | J22: 1（小硬直） | K22: 无 | L22: 帚星 | M22: 母亲杖 | N22: 普通石 | O22: 25 | P22: 1925 | Q22: 0 | R22: 292 | S22: 0 | T22: 0 | U22: 0 | V22: 12 | W22: 0 | X22: 55 | Y22: 0 | Z22: 55 | AA22: 15 | AB22: 15 | AC22: 15 | AD22: 15 | AE22: 15 | AF22: 3 | AG22: 3 | AH22: 3 | AI22: 3 | AJ22: 3 | AK22: 20030 | AL22: 0 | AM22: 0 | AN22: 1.65 | AO22: 0 | AP22: 1.65 | AQ22: 0 | AR22: 0 | AS22: 1.65 | AT22: 0 | AU22: 1.65 | AV22: 0 | AW22: 0 | AX22: 1.65 | AY22: 0 | AZ22: 1.65 | BA22: 0 | BB22: 0 | BC22: 1.65 | BD22: 0 | BE22: 1.65 | BF22: 0 | BG22: 0 | BH22: 1.65 | BI22: 0 | BJ22: 1.65 | BK22: 0 | BL22: 1255.6 | BM22: 0 | BN22: 0 | BO22: 0 | BP22: 无 | BQ22: 亚兹勒1 | BR22: 无 | BS22: 无 | BT22: 1 | BU22: 指头 | BV22: 1 | BW22: 1 | BX22: 1 | BY22: 1 | BZ22: 1 | CA22: 1 | CB22: 0 | CC22: 1898.4672 | CD22: 0 | CE22: 0 | CF22: 0 | CG22: 0 | CI22: 6 | CJ22: 0 | CK22: 0 | CL22: 24 | CM22: 1.03
A23: 魔法 | B23: 帚星-蓄力 | C23: 母亲杖 | D23: 2373 | E23: 魔 | F23: 365 | G23: 亚兹勒1,蓄力 | H23: 12.95 | I23: 12.95 | J23: 2（中硬直） | K23: 无 | L23: 帚星-蓄力 | M23: 母亲杖 | N23: 普通石 | O23: 25 | P23: 1925 | Q23: 0 | R23: 365 | S23: 0 | T23: 0 | U23: 0 | V23: 12 | W23: 0 | X23: 55 | Y23: 0 | Z23: 55 | AA23: 15 | AB23: 15 | AC23: 15 | AD23: 15 | AE23: 15 | AF23: 3 | AG23: 3 | AH23: 3 | AI23: 3 | AJ23: 3 | AK23: 20030 | AL23: 0 | AM23: 0 | AN23: 1.65 | AO23: 0 | AP23: 1.65 | AQ23: 0 | AR23: 0 | AS23: 1.65 | AT23: 0 | AU23: 1.65 | AV23: 0 | AW23: 0 | AX23: 1.65 | AY23: 0 | AZ23: 1.65 | BA23: 0 | BB23: 0 | BC23: 1.65 | BD23: 0 | BE23: 1.65 | BF23: 0 | BG23: 0 | BH23: 1.65 | BI23: 0 | BJ23: 1.65 | BK23: 0 | BL23: 1569.5 | BM23: 0 | BN23: 0 | BO23: 0 | BP23: 无 | BQ23: 亚兹勒1 | BR23: 蓄力 | BS23: 无 | BT23: 1 | BU23: 指头 | BV23: 1 | BW23: 1 | BX23: 1 | BY23: 1 | BZ23: 1 | CA23: 1 | CB23: 0 | CC23: 2373.084 | CD23: 0 | CE23: 0 | CF23: 0 | CG23: 0 | CI23: 6 | CJ23: 0 | CK23: 0 | CL23: 24 | CM23: 1.03
A24: 魔法 | B24: 萨米尔冰风暴-蓄力第一下 | C24: 母亲杖 | D24: 640 | E24: 魔 | F24: 104 | G24: 冰魔法,蓄力,风暴 | H24: 10.18 | I24: 10.18 | J24: 8（微小硬直） | K24: 80冰冻值 | L24: 萨米尔冰风暴-蓄力第一下 | M24: 母亲杖 | N24: 普通石 | O24: 25 | P24: 1925 | Q24: 0 | R24: 104 | S24: 0 | T24: 0 | U24: 0 | V24: 12 | W24: 0 | X24: 55 | Y24: 0 | Z24: 55 | AA24: 15 | AB24: 15 | AC24: 15 | AD24: 15 | AE24: 15 | AF24: 3 | AG24: 3 | AH24: 3 | AI24: 3 | AJ24: 3 | AK24: 20030 | AL24: 0 | AM24: 0 | AN24: 1.65 | AO24: 0 | AP24: 1.65 | AQ24: 0 | AR24: 0 | AS24: 1.65 | AT24: 0 | AU24: 1.65 | AV24: 0 | AW24: 0 | AX24: 1.65 | AY24: 0 | AZ24: 1.65 | BA24: 0 | BB24: 0 | BC24: 1.65 | BD24: 0 | BE24: 1.65 | BF24: 0 | BG24: 0 | BH24: 1.65 | BI24: 0 | BJ24: 1.65 | BK24: 0 | BL24: 447.2 | BM24: 0 | BN24: 0 | BO24: 0 | BP24: 无 | BQ24: 冰魔法 | BR24: 蓄力 | BS24: 风暴 | BT24: 1 | BU24: 指头 | BV24: 1 | BW24: 1 | BX24: 1 | BY24: 1 | BZ24: 1 | CA24: 1 | CB24: 0 | CC24: 640.591 | CD24: 0 | CE24: 0 | CF24: 0 | CG24: 80 | CH24: 冰冻值 | CI24: 6 | CJ24: 0 | CK24: 0 | CL24: 17 | CM24: 1.03
A25: 祷告 | B25: 血焰爪痕 | C25: 龙飨印记 | D25: 2115 | E25: 火 | F25: 236 | H25: 10.18 | I25: 10.18 | J25: 2（中硬直） | K25: 100出血值 | L25: 血焰爪痕 | M25: 龙飨印记 | N25: 失色石 | O25: 10 | P25: 2410 | Q25: 0 | R25: 0 | S25: 236 | T25: 0 | U25: 0 | V25: 0 | W25: 0 | X25: 0 | Y25: 30 | Z25: 75 | AA25: 12 | AB25: 12 | AC25: 12 | AD25: 12 | AE25: 12 | AF25: 3 | AG25: 3 | AH25: 3 | AI25: 3 | AJ25: 3 | AK25: 30030 | AL25: 0 | AM25: 0 | AN25: 0 | AO25: 0.9 | AP25: 2.25 | AQ25: 0 | AR25: 0 | AS25: 0 | AT25: 0.9 | AU25: 2.25 | AV25: 0 | AW25: 0 | AX25: 0 | AY25: 0.9 | AZ25: 2.25 | BA25: 0 | BB25: 0 | BC25: 0 | BD25: 0.9 | BE25: 2.25 | BF25: 0 | BG25: 0 | BH25: 0 | BI25: 0.9 | BJ25: 2.25 | BK25: 0 | BL25: 0 | BM25: 979.4 | BN25: 0 | BO25: 0 | BP25: 无 | BQ25: 无 | BR25: 无 | BS25: 无 | BT25: 1 | BU25: 龙飨 | BV25: 1 | BW25: 1 | BX25: 1 | BY25: 1 | BZ25: 1 | CA25: 1 | CB25: 0 | CC25: 0 | CD25: 2115.504 | CE25: 0 | CF25: 0 | CG25: 0 | CI25: 11 | CJ25: 0 | CK25: 100 | CL25: 12 | CM25: 1
A26: 祷告 | B26: 贝勒的焰雷 | C26: 龙飨印记 | D26: 5226 | E26: 普通+火+雷 | F26: 280+220+280 | G26: 龙飨 | H26: 30 | I26: 30 | J26: 4（大击退） | K26: 无 | L26: 贝勒的焰雷 | M26: 龙飨印记 | N26: 失色石 | O26: 10 | P26: 2410 | Q26: 280 | R26: 0 | S26: 220 | T26: 280 | U26: 0 | V26: 0 | W26: 0 | X26: 0 | Y26: 30 | Z26: 75 | AA26: 12 | AB26: 12 | AC26: 12 | AD26: 12 | AE26: 12 | AF26: 3 | AG26: 3 | AH26: 3 | AI26: 3 | AJ26: 3 | AK26: 30030 | AL26: 0 | AM26: 0 | AN26: 0 | AO26: 0.9 | AP26: 2.25 | AQ26: 0 | AR26: 0 | AS26: 0 | AT26: 0.9 | AU26: 2.25 | AV26: 0 | AW26: 0 | AX26: 0 | AY26: 0.9 | AZ26: 2.25 | BA26: 0 | BB26: 0 | BC26: 0 | BD26: 0.9 | BE26: 2.25 | BF26: 0 | BG26: 0 | BH26: 0 | BI26: 0.9 | BJ26: 2.25 | BK26: 1162 | BL26: 0 | BM26: 913 | BN26: 1162 | BO26: 0 | BP26: 普通 | BQ26: 龙飨 | BR26: 无 | BS26: 无 | BT26: 1.15 | BU26: 龙飨 | BV26: 1.15 | BW26: 1 | BX26: 1 | BY26: 1 | BZ26: 1 | CA26: 1 | CB26: 938.0826 | CC26: 0 | CD26: 2267.892 | CE26: 2020.4856 | CF26: 0 | CG26: 0 | CI26: 11 | CJ26: 0 | CK26: 0 | CL26: 43 | CM26: 1
A27: 祷告 | B27: 桂奥尔的咆哮 | C27: 龙飨印记 | D27: 1072 | E27: 普通 | F27: 320 | G27: 龙飨,吐息 | H27: 16.11 | I27: 16.11 | J27: 7（击退） | K27: 无 | L27: 桂奥尔的咆哮 | M27: 龙飨印记 | N27: 失色石 | O27: 10 | P27: 2410 | Q27: 320 | R27: 0 | S27: 0 | T27: 0 | U27: 0 | V27: 0 | W27: 0 | X27: 0 | Y27: 30 | Z27: 75 | AA27: 12 | AB27: 12 | AC27: 12 | AD27: 12 | AE27: 12 | AF27: 3 | AG27: 3 | AH27: 3 | AI27: 3 | AJ27: 3 | AK27: 30030 | AL27: 0 | AM27: 0 | AN27: 0 | AO27: 0.9 | AP27: 2.25 | AQ27: 0 | AR27: 0 | AS27: 0 | AT27: 0.9 | AU27: 2.25 | AV27: 0 | AW27: 0 | AX27: 0 | AY27: 0.9 | AZ27: 2.25 | BA27: 0 | BB27: 0 | BC27: 0 | BD27: 0.9 | BE27: 2.25 | BF27: 0 | BG27: 0 | BH27: 0 | BI27: 0.9 | BJ27: 2.25 | BK27: 1328 | BL27: 0 | BM27: 0 | BN27: 0 | BO27: 0 | BP27: 普通 | BQ27: 龙飨 | BR27: 吐息 | BS27: 无 | BT27: 1.15 | BU27: 龙飨 | BV27: 1.15 | BW27: 1 | BX27: 1 | BY27: 1 | BZ27: 1 | CA27: 1 | CB27: 1072.0944 | CC27: 0 | CD27: 0 | CE27: 0 | CF27: 0 | CG27: 0 | CI27: 11 | CJ27: 0 | CK27: 0 | CL27: 50 | CM27: 1
A28: 祷告 | B28: 癫火 | C28: 龙飨印记 | D28: 907 | E28: 火 | F28: 107 | G28: 癫火 | H28: 5 | I28: 5 | J28: 2（中硬直） | K28: 30发狂值 | L28: 癫火 | M28: 龙飨印记 | N28: 失色石 | O28: 10 | P28: 2410 | Q28: 0 | R28: 0 | S28: 107 | T28: 0 | U28: 0 | V28: 0 | W28: 0 | X28: 0 | Y28: 30 | Z28: 75 | AA28: 12 | AB28: 12 | AC28: 12 | AD28: 12 | AE28: 12 | AF28: 3 | AG28: 3 | AH28: 3 | AI28: 3 | AJ28: 3 | AK28: 30030 | AL28: 0 | AM28: 0 | AN28: 0 | AO28: 0.9 | AP28: 2.25 | AQ28: 0 | AR28: 0 | AS28: 0 | AT28: 0.9 | AU28: 2.25 | AV28: 0 | AW28: 0 | AX28: 0 | AY28: 0.9 | AZ28: 2.25 | BA28: 0 | BB28: 0 | BC28: 0 | BD28: 0.9 | BE28: 2.25 | BF28: 0 | BG28: 0 | BH28: 0 | BI28: 0.9 | BJ28: 2.25 | BK28: 0 | BL28: 0 | BM28: 444.05 | BN28: 0 | BO28: 0 | BP28: 无 | BQ28: 癫火 | BR28: 无 | BS28: 无 | BT28: 1 | BU28: 龙飨 | BV28: 1 | BW28: 1 | BX28: 1 | BY28: 1 | BZ28: 1 | CA28: 1 | CB28: 0 | CC28: 0 | CD28: 907.25983 | CE28: 0 | CF28: 0 | CG28: 21 | CH28: 发狂值 | CI28: 11 | CJ28: 1 | CK28: 0 | CL28: 16 | CM28: 1
A29: 祷告 | B29: 火焰啊！-蓄力 | C29: 龙飨印记 | D29: 3451 | E29: 火 | F29: 385 | G29: 巨人,蓄力 | H29: 14.4 | I29: 14.4 | J29: 3（大硬直） | K29: 无 | L29: 火焰啊！-蓄力 | M29: 龙飨印记 | N29: 失色石 | O29: 10 | P29: 2410 | Q29: 0 | R29: 0 | S29: 385 | T29: 0 | U29: 0 | V29: 0 | W29: 0 | X29: 0 | Y29: 30 | Z29: 75 | AA29: 12 | AB29: 12 | AC29: 12 | AD29: 12 | AE29: 12 | AF29: 3 | AG29: 3 | AH29: 3 | AI29: 3 | AJ29: 3 | AK29: 30030 | AL29: 0 | AM29: 0 | AN29: 0 | AO29: 0.9 | AP29: 2.25 | AQ29: 0 | AR29: 0 | AS29: 0 | AT29: 0.9 | AU29: 2.25 | AV29: 0 | AW29: 0 | AX29: 0 | AY29: 0.9 | AZ29: 2.25 | BA29: 0 | BB29: 0 | BC29: 0 | BD29: 0.9 | BE29: 2.25 | BF29: 0 | BG29: 0 | BH29: 0 | BI29: 0.9 | BJ29: 2.25 | BK29: 0 | BL29: 0 | BM29: 1597.75 | BN29: 0 | BO29: 0 | BP29: 无 | BQ29: 巨人 | BR29: 蓄力 | BS29: 无 | BT29: 1 | BU29: 龙飨 | BV29: 1 | BW29: 1 | BX29: 1 | BY29: 1 | BZ29: 1 | CA29: 1 | CB29: 0 | CC29: 0 | CD29: 3451.14 | CE29: 0 | CF29: 0 | CG29: 0 | CI29: 11 | CJ29: 0 | CK29: 0 | CL29: 16 | CM29: 1
A30: 祷告 | B30: 龙咬 | C30: 龙飨印记 | D30: 2103 | E30: 普通 | F30: 628 | G30: 龙飨 | H30: 45 | I30: 45 | J30: 7（击退） | K30: 无 | L30: 龙咬 | M30: 龙飨印记 | N30: 失色石 | O30: 10 | P30: 2410 | Q30: 628 | R30: 0 | S30: 0 | T30: 0 | U30: 0 | V30: 0 | W30: 0 | X30: 0 | Y30: 30 | Z30: 75 | AA30: 12 | AB30: 12 | AC30: 12 | AD30: 12 | AE30: 12 | AF30: 3 | AG30: 3 | AH30: 3 | AI30: 3 | AJ30: 3 | AK30: 30030 | AL30: 0 | AM30: 0 | AN30: 0 | AO30: 0.9 | AP30: 2.25 | AQ30: 0 | AR30: 0 | AS30: 0 | AT30: 0.9 | AU30: 2.25 | AV30: 0 | AW30: 0 | AX30: 0 | AY30: 0.9 | AZ30: 2.25 | BA30: 0 | BB30: 0 | BC30: 0 | BD30: 0.9 | BE30: 2.25 | BF30: 0 | BG30: 0 | BH30: 0 | BI30: 0.9 | BJ30: 2.25 | BK30: 2606.2 | BL30: 0 | BM30: 0 | BN30: 0 | BO30: 0 | BP30: 普通 | BQ30: 龙飨 | BR30: 无 | BS30: 无 | BT30: 1.15 | BU30: 龙飨 | BV30: 1.15 | BW30: 1 | BX30: 1 | BY30: 1 | BZ30: 1 | CA30: 1 | CB30: 2103.9853 | CC30: 0 | CD30: 0 | CE30: 0 | CF30: 0 | CG30: 0 | CI30: 11 | CJ30: 0 | CK30: 0 | CL30: 34 | CM30: 1
A31: 祷告 | B31: 古龙雷击 | C31: 龙飨印记 | D31: 1989 | E31: 雷 | F31: 317 | G31: 古龙 | H31: 5 | I31: 5 | J31: 1（小硬直） | K31: 无 | L31: 古龙雷击 | M31: 龙飨印记 | N31: 失色石 | O31: 10 | P31: 2410 | Q31: 0 | R31: 0 | S31: 0 | T31: 317 | U31: 0 | V31: 0 | W31: 0 | X31: 0 | Y31: 30 | Z31: 75 | AA31: 12 | AB31: 12 | AC31: 12 | AD31: 12 | AE31: 12 | AF31: 3 | AG31: 3 | AH31: 3 | AI31: 3 | AJ31: 3 | AK31: 30030 | AL31: 0 | AM31: 0 | AN31: 0 | AO31: 0.9 | AP31: 2.25 | AQ31: 0 | AR31: 0 | AS31: 0 | AT31: 0.9 | AU31: 2.25 | AV31: 0 | AW31: 0 | AX31: 0 | AY31: 0.9 | AZ31: 2.25 | BA31: 0 | BB31: 0 | BC31: 0 | BD31: 0.9 | BE31: 2.25 | BF31: 0 | BG31: 0 | BH31: 0 | BI31: 0.9 | BJ31: 2.25 | BK31: 0 | BL31: 0 | BM31: 0 | BN31: 1315.55 | BO31: 0 | BP31: 无 | BQ31: 古龙 | BR31: 无 | BS31: 无 | BT31: 1 | BU31: 龙飨 | BV31: 1 | BW31: 1 | BX31: 1 | BY31: 1 | BZ31: 1 | CA31: 1 | CB31: 0 | CC31: 0 | CD31: 0 | CE31: 1989.1116 | CF31: 0 | CG31: 0 | CI31: 11 | CJ31: 0 | CK31: 0 | CL31: 36 | CM31: 1
A32: 祷告 | B32: 黄金大弯弧 | C32: 龙飨印记 | D32: 1349 | E32: 圣 | F32: 215 | G32: 螺旋 | H32: 8 | I32: 8 | J32: 1（小硬直） | K32: 无 | L32: 黄金大弯弧 | M32: 龙飨印记 | N32: 失色石 | O32: 10 | P32: 2410 | Q32: 0 | R32: 0 | S32: 0 | T32: 0 | U32: 215 | V32: 0 | W32: 0 | X32: 0 | Y32: 30 | Z32: 75 | AA32: 12 | AB32: 12 | AC32: 12 | AD32: 12 | AE32: 12 | AF32: 3 | AG32: 3 | AH32: 3 | AI32: 3 | AJ32: 3 | AK32: 30030 | AL32: 0 | AM32: 0 | AN32: 0 | AO32: 0.9 | AP32: 2.25 | AQ32: 0 | AR32: 0 | AS32: 0 | AT32: 0.9 | AU32: 2.25 | AV32: 0 | AW32: 0 | AX32: 0 | AY32: 0.9 | AZ32: 2.25 | BA32: 0 | BB32: 0 | BC32: 0 | BD32: 0.9 | BE32: 2.25 | BF32: 0 | BG32: 0 | BH32: 0 | BI32: 0.9 | BJ32: 2.25 | BK32: 0 | BL32: 0 | BM32: 0 | BN32: 0 | BO32: 892.25 | BP32: 无 | BQ32: 螺旋 | BR32: 无 | BS32: 无 | BT32: 1 | BU32: 龙飨 | BV32: 1 | BW32: 1 | BX32: 1 | BY32: 1 | BZ32: 1 | CA32: 1 | CB32: 0 | CC32: 0 | CD32: 0 | CE32: 0 | CF32: 1349.082 | CG32: 0 | CI32: 11 | CJ32: 0 | CK32: 0 | CL32: 24 | CM32: 1
A33: 祷告 | B33: 死亡雷击 | C33: 龙飨印记 | D33: 3218 | E33: 雷 | F33: 513 | G33: 古龙 | H33: 5 | I33: 5 | J33: 2（中硬直） | K33: 50死亡值 | L33: 死亡雷击 | M33: 龙飨印记 | N33: 失色石 | O33: 10 | P33: 2410 | Q33: 0 | R33: 0 | S33: 0 | T33: 513 | U33: 0 | V33: 0 | W33: 0 | X33: 0 | Y33: 30 | Z33: 75 | AA33: 12 | AB33: 12 | AC33: 12 | AD33: 12 | AE33: 12 | AF33: 3 | AG33: 3 | AH33: 3 | AI33: 3 | AJ33: 3 | AK33: 30030 | AL33: 0 | AM33: 0 | AN33: 0 | AO33: 0.9 | AP33: 2.25 | AQ33: 0 | AR33: 0 | AS33: 0 | AT33: 0.9 | AU33: 2.25 | AV33: 0 | AW33: 0 | AX33: 0 | AY33: 0.9 | AZ33: 2.25 | BA33: 0 | BB33: 0 | BC33: 0 | BD33: 0.9 | BE33: 2.25 | BF33: 0 | BG33: 0 | BH33: 0 | BI33: 0.9 | BJ33: 2.25 | BK33: 0 | BL33: 0 | BM33: 0 | BN33: 2128.95 | BO33: 0 | BP33: 无 | BQ33: 古龙 | BR33: 无 | BS33: 无 | BT33: 1 | BU33: 龙飨 | BV33: 1 | BW33: 1 | BX33: 1 | BY33: 1 | BZ33: 1 | CA33: 1 | CB33: 0 | CC33: 0 | CD33: 0 | CE33: 3218.9724 | CF33: 0 | CG33: 50 | CH33: 死亡值 | CI33: 11 | CJ33: 0 | CK33: 0 | CL33: 28 | CM33: 1
A34: 祷告 | B34: 感受巨人火焰吧 | C34: 龙飨印记 | D34: 2913 | E34: 火 | F34: 325 | G34: 巨人 | H34: 13.63 | I34: 13.63 | J34: 7（击退） | K34: 无 | L34: 感受巨人火焰吧 | M34: 龙飨印记 | N34: 失色石 | O34: 10 | P34: 2410 | Q34: 0 | R34: 0 | S34: 325 | T34: 0 | U34: 0 | V34: 0 | W34: 0 | X34: 0 | Y34: 30 | Z34: 75 | AA34: 12 | AB34: 12 | AC34: 12 | AD34: 12 | AE34: 12 | AF34: 3 | AG34: 3 | AH34: 3 | AI34: 3 | AJ34: 3 | AK34: 30030 | AL34: 0 | AM34: 0 | AN34: 0 | AO34: 0.9 | AP34: 2.25 | AQ34: 0 | AR34: 0 | AS34: 0 | AT34: 0.9 | AU34: 2.25 | AV34: 0 | AW34: 0 | AX34: 0 | AY34: 0.9 | AZ34: 2.25 | BA34: 0 | BB34: 0 | BC34: 0 | BD34: 0.9 | BE34: 2.25 | BF34: 0 | BG34: 0 | BH34: 0 | BI34: 0.9 | BJ34: 2.25 | BK34: 0 | BL34: 0 | BM34: 1348.75 | BN34: 0 | BO34: 0 | BP34: 无 | BQ34: 巨人 | BR34: 无 | BS34: 无 | BT34: 1 | BU34: 龙飨 | BV34: 1 | BW34: 1 | BX34: 1 | BY34: 1 | BZ34: 1 | CA34: 1 | CB34: 0 | CC34: 0 | CD34: 2913.3 | CE34: 0 | CF34: 0 | CG34: 0 | CI34: 11 | CJ34: 0 | CK34: 0 | CL34: 30 | CM34: 1

Sheet 对比计算
A1: 法术伤害对比计算器 v1.16 by: 虚空蛋黄酱
A2: 大致模拟了一下所有法术打恶兆的伤害，因为不同法术性能、范围差异巨大，数据仅供参考，暂不支持上buff。 如果想修改攻击的段数，在AtkParam表内修改。
A3: 人物属性 | H3: dlc专属
A4: 力 | B4: 敏 | C4: 智 | D4: 信 | E4: 感 | F4: 普通石强化 | G4: 失色石强化 | H4: 幽影树庇佑 | I4: 人物加伤
A5: 99 | B5: 99 | C5: 99 | D5: 99 | E5: 99 | F5: 25 | G5: 10 | H5: 20 | I5: =HLOOKUP(H5,Curve!B19:V20,2, )-1 -> 1.05
A6: 触媒属性 | K6: 计算 | L6: 力补正 | M6: 敏补正 | N6: 智补正 | O6: 信补正 | P6: 感补正 | Q6: 失色石 | R6: 强化曲线 | S6: 力补正成长 | T6: 敏补正成长 | U6: 智补正成长 | V6: 信补正成长 | W6: 感补正成长 | X6: 补正修正 | Y6: 物成长 | Z6: 魔成长 | AA6: 火成长 | AB6: 雷成长 | AC6: 圣成长 | AD6: 满足需求 | AE6: 物法强 | AF6: 魔法强 | AG6: 火法强 | AH6: 雷法强 | AI6: 圣法强 | AJ6: 异常成长 | AK6: 异常补正 | AL6: 特殊加成 | AM6: 类型
A7: 法杖 | B7: 圣印记 | C7: 普通石强化 | D7: 失色石强化 | E7: 物法强 | F7: 魔法强 | G7: 火法强 | H7: 雷法强 | I7: 圣法强 | J7: 法杖 | K7: =A8 -> 母亲杖 | L7: {=INDEX(Weapon!$I$2:$M$35,MATCH(K7,Weapon!$B$2:$B$35,),)} -> 12 | M7: 0 | N7: 55 | O7: 0 | P7: 55 | Q7: =_xlfn.XLOOKUP(K7,Weapon!B:B,Weapon!G:G) -> 0 | R7: {=_xlfn.XLOOKUP(K7,Weapon!B:B,Weapon!H:H)+_xlfn.IFS(K7="陨石杖",,Q7,$G$5,1,$F$5)} -> 1925 | S7: {=INDEX(WeaponUP!$B$2:$F$877,MATCH(R7,WeaponUP!$A$2:$A$877,),)} -> 3 | T7: 3 | U7: 3 | V7: 3 | W7: 3 | X7: =_xlfn.XLOOKUP(K7,Weapon!B:B,Weapon!T:T) -> 20030 | Y7: {=INDEX(Weapon!$N$2:$R$35,MATCH(K7,Weapon!$B$2:$B$35,),)} -> 15 | Z7: 15 | AA7: 15 | AB7: 15 | AC7: 15 | AD7: {=AND($C$5:$E$5>INDEX(Weapon!$D$2:$F$35,MATCH(K7,Weapon!$B$2:$B$35,),))} -> TRUE | AE7: {=IF(AD7,TRANSPOSE(1+_xlfn.BYROW(_xlfn.WRAPROWS(INDEX(AtkCorrect!$B$2:$Z$185,MATCH(X7,AtkCorrect!$A$2:$A$185,),),5)*_xlfn.ANCHORARRAY(L7)%*_xlfn.ANCHORARRAY(S7)*INDEX(Curve!$B$2:$EU$18,_xlfn.ANCHORARRAY(Y7)+1,$A$5:$E$5)%,_xleta.SUM)),0.6*S7^0)} -> 4.3 | AF7: 4.3 | AG7: 4.3 | AH7: 4.3 | AI7: 4.3 | AJ7: =_xlfn.XLOOKUP(K7,Weapon!B:B,Weapon!S:S) -> 6 | AK7: {=1+P7%*W7*INDEX(Curve!$B$2:$EU$18,AJ7+1,$E$5)%} -> 2.65 | AL7: =_xlfn.XLOOKUP($K7,Weapon!$B:$B,Weapon!V:V) -> 1.15 | AM7: =_xlfn.XLOOKUP($K7,Weapon!$B:$B,Weapon!W:W) -> 指头
A8: 母亲杖 | B8: 龙飨印记 | C8: 25 | D8: 10 | E8: {=IF(D11="魔法",_xlfn.ANCHORARRAY(AE7),_xlfn.ANCHORARRAY(AE8))*100} -> 430 | F8: 430 | G8: 430 | H8: 430 | I8: 430 | J8: 圣印记 | K8: =B8 -> 龙飨印记 | L8: {=INDEX(Weapon!$I$2:$M$35,MATCH(K8,Weapon!$B$2:$B$35,),)} -> 0 | M8: 0 | N8: 0 | O8: 30 | P8: 75 | Q8: =_xlfn.XLOOKUP(K8,Weapon!B:B,Weapon!G:G) -> 2200 | R8: {=_xlfn.XLOOKUP(K8,Weapon!B:B,Weapon!H:H)+_xlfn.IFS(K8="陨石杖",,Q8,$G$5,1,$F$5)} -> 2410 | S8: {=INDEX(WeaponUP!$B$2:$F$877,MATCH(R8,WeaponUP!$A$2:$A$877,),)} -> 3 | T8: 3 | U8: 3 | V8: 3 | W8: 3 | X8: =_xlfn.XLOOKUP(K8,Weapon!B:B,Weapon!T:T) -> 30030 | Y8: {=INDEX(Weapon!$N$2:$R$35,MATCH(K8,Weapon!$B$2:$B$35,),)} -> 12 | Z8: 12 | AA8: 12 | AB8: 12 | AC8: 12 | AD8: {=AND($C$5:$E$5>INDEX(Weapon!$D$2:$F$35,MATCH(K8,Weapon!$B$2:$B$35,),))} -> TRUE | AE8: {=IF(AD8,TRANSPOSE(1+_xlfn.BYROW(_xlfn.WRAPROWS(INDEX(AtkCorrect!$B$2:$Z$185,MATCH(X8,AtkCorrect!$A$2:$A$185,),),5)*_xlfn.ANCHORARRAY(L8)%*_xlfn.ANCHORARRAY(S8)*INDEX(Curve!$B$2:$EU$18,_xlfn.ANCHORARRAY(Y8)+1,$A$5:$E$5)%,_xleta.SUM)),0.6*S8^0)} -> 4.15 | AF8: 4.15 | AG8: 4.15 | AH8: 4.15 | AI8: 4.15 | AJ8: =_xlfn.XLOOKUP(K8,Weapon!B:B,Weapon!S:S) -> 11 | AK8: {=1+P8%*W8*INDEX(Curve!$B$2:$EU$18,AJ8+1,$E$5)%} -> 1.45 | AL8: =_xlfn.XLOOKUP($K8,Weapon!$B:$B,Weapon!V:V) -> 1.15 | AM8: =_xlfn.XLOOKUP($K8,Weapon!$B:$B,Weapon!W:W) -> 龙飨
A9: 敌人属性 | D9: 法术信息 | G9: 触媒属性
A10: 敌人 | B10: 周目数 | C10: 是否为dlc | D10: 类型 | E10: 是否蓄力/持续 | F10: 无限持续类重复 | G10: 异常补正 | H10: 特殊加成 | I10: 加成类型
A11: 下水道恶兆之子 | B11: 1 | C11: =_xlfn.XLOOKUP(A11,敌人数据!A:A,敌人数据!S:S) -> 否 | D11: 魔法 | E11: 是 | F11: 5 | G11: =IF(D11="魔法",AK7,AK8) -> 2.65 | H11: =IF($D$11="魔法",AL7,AL8) -> 1.15 | I11: =IF($D$11="魔法",AM7,AM8) -> 指头
B12: 普通 | C12: 打击 | D12: 斩击 | E12: 突刺 | F12: 魔 | G12: 火 | H12: 雷 | I12: 圣
A13: 防御 | B13: {=IF(LEN(B12:I12),INDEX(敌人数据!C1:J51,MATCH(A11,敌人数据!A1:A51,),MATCH(B11,敌人数据!C1:J1,)))} -> 117 | C13: 117 | D13: 117 | E13: 117 | F13: 117 | G13: 117 | H13: 117 | I13: 117
A14: 伤害倍率 | B14: {=INDEX(敌人数据!K1:R51,MATCH(A11,敌人数据!A1:A51,),)%} -> 1 | C14: 1 | D14: 1.1 | E14: 1 | F14: 1 | G14: 1 | H14: 1 | I14: 0.8
A15: 点击-/+即可显示/隐藏所有信息
A16: 魔法/祷告 | B16: 总伤害 | C16: 伤害类型 | D16: 蓄力/持续 | E16: 一周目削韧 | F16: ="当前周目"&CHAR(10)&TEXT(B11,"[DBNum1]")&"周目削韧" -> 当前周目 一周目削韧 | G16: 冲击力 | H16: 异常值 | I16: 耗蓝 | J16: 物伤害 | K16: 魔伤害 | L16: 火伤害 | M16: 雷伤害 | N16: 圣伤害 | O16: 特殊加成 | P16: ID 1 | Q16: ID 2 | R16: ID 3 | S16: ID 4 | T16: ID 5 | U16: ID 6 | V16: 持续id 1 | W16: 持续id 2 | X16: 持续id 3 | Y16: 次数1 | Z16: 次数2 | AA16: 次数3 | AB16: 次数4 | AC16: 次数5 | AD16: 次数6 | AE16: 物属性1 | AF16: 物属性2 | AG16: 物属性3 | AH16: 物属性4 | AI16: 物属性5 | AJ16: 物属性6 | AK16: 物攻击1 | AL16: 物攻击2 | AM16: 物攻击3 | AN16: 物攻击4 | AO16: 物攻击5 | AP16: 物攻击6 | AQ16: 物伤害1 | AR16: 物伤害2 | AS16: 物伤害3 | AT16: 物伤害4 | AU16: 物伤害5 | AV16: 物伤害6 | AW16: 魔攻击1 | AX16: 魔攻击2 | AY16: 魔攻击3 | AZ16: 魔攻击4 | BA16: 魔攻击5 | BB16: 魔攻击6 | BC16: 魔伤害1 | BD16: 魔伤害2 | BE16: 魔伤害3 | BF16: 魔伤害4 | BG16: 魔伤害5 | BH16: 魔伤害6 | BI16: 火攻击1 | BJ16: 火攻击2 | BK16: 火攻击3 | BL16: 火攻击4 | BM16: 火攻击5 | BN16: 火攻击6 | BO16: 火伤害1 | BP16: 火伤害2 | BQ16: 火伤害3 | BR16: 火伤害4 | BS16: 火伤害5 | BT16: 火伤害6 | BU16: 雷攻击1 | BV16: 雷攻击2 | BW16: 雷攻击3 | BX16: 雷攻击4 | BY16: 雷攻击5 | BZ16: 雷攻击6 | CA16: 雷伤害1 | CB16: 雷伤害2 | CC16: 雷伤害3 | CD16: 雷伤害4 | CE16: 雷伤害5 | CF16: 雷伤害6 | CG16: 圣攻击1 | CH16: 圣攻击2 | CI16: 圣攻击3 | CJ16: 圣攻击4 | CK16: 圣攻击5 | CL16: 圣攻击6 | CM16: 圣伤害1 | CN16: 圣伤害2 | CO16: 圣伤害3 | CP16: 圣伤害4 | CQ16: 圣伤害5 | CR16: 圣伤害6 | CS16: 削韧1 | CT16: 削韧2 | CU16: 削韧3 | CV16: 削韧4 | CW16: 削韧5 | CX16: 削韧6 | CY16: 冲击力1 | CZ16: 冲击力2 | DA16: 冲击力3 | DB16: 冲击力4 | DC16: 冲击力5 | DD16: 冲击力6 | DE16: 异常值1 | DF16: 异常值2 | DG16: 异常值3 | DH16: 异常值4 | DI16: 异常值5 | DJ16: 异常值6 | DK16: 异常类型 | DL16: 血焰
A17: {=IF(D11="魔法",SpellData!A2:A75,SpellData!A76:A167)} -> 辉石魔砾 | B17: {=_xlfn.BYROW(_xlfn.ANCHORARRAY(J17):_xlfn.ANCHORARRAY(N17),_xleta.SUM)} -> 563 | C17: {=_xlfn.BYROW(IF(_xlfn.ANCHORARRAY(J17):_xlfn.ANCHORARRAY(N17),IF({1,0,0,0,0},_xlfn.ANCHORARRAY(AE17),LEFT(J16:N16)),""),_xlfn.LAMBDA(_xlpm.x,_xlfn.TEXTJOIN("+",,_xlpm.x)))} -> 魔 | D17: {=IF(_xlfn.XLOOKUP(_xlfn.ANCHORARRAY(A17),SpellData!A:A,SpellData!F:F)*(E11="是"),"是","否")} -> 否 | E17: {=ROUND(_xlfn.BYROW(_xlfn.ANCHORARRAY(CS17):_xlfn.ANCHORARRAY(CX17)*_xlfn.ANCHORARRAY(Y17):_xlfn.ANCHORARRAY(AD17),_xleta.SUM),2)} -> 3 | F17: {=ROUND(_xlfn.ANCHORARRAY(E17)*INDEX({1,1,0.95,0.9,0.85,0.8,0.7,0.6},B11),2)} -> 3 | G17: {=_xlfn.BYROW(_xlfn.ANCHORARRAY(CY17):_xlfn.ANCHORARRAY(DD17),_xlfn.LAMBDA(_xlpm.x,_xlfn.TEXTJOIN("+",,_xlpm.x)))} -> 1 | H17: {=_xlfn.LET(_xlpm.p,_xlfn.BYROW(_xlfn.ANCHORARRAY(DE17):_xlfn.ANCHORARRAY(DJ17)*_xlfn.ANCHORARRAY(Y17):_xlfn.ANCHORARRAY(AD17),_xlfn.LAMBDA(_xlpm.x,SUM(INT(_xlpm.x))))*IF((_xlfn.ANCHORARRAY(DK17)="出血值")+(_xlfn.ANCHORARRAY(DK17)="发狂值"),G11,1),_xlpm.q,_xlfn.ANCHORARRAY(DL17),_xlfn.IFS(_xlpm.q,_xlpm.q&"出血值",_xlpm.p,INT(_xlpm.p)&_xlfn.ANCHORARRAY(DK17),1,"无"))} -> 无 | I17: {=VLOOKUP(_xlfn.ANCHORARRAY(A17),SpellData!A:D,IF(E11="是",4,3),)+_xlfn.XLOOKUP(_xlfn.ANCHORARRAY(A17),SpellData!A:A,SpellData!E:E)*F11} -> 7 | J17: {=INT(_xlfn.BYROW(_xlfn.ANCHORARRAY(AQ17):_xlfn.ANCHORARRAY(AV17),_xleta.SUM)*_xlfn.ANCHORARRAY(O17))} -> 0 | K17: {=INT(_xlfn.BYROW(_xlfn.ANCHORARRAY(BC17):_xlfn.ANCHORARRAY(BH17),_xleta.SUM)*_xlfn.ANCHORARRAY(O17))} -> 563 | L17: {=INT(_xlfn.BYROW(_xlfn.ANCHORARRAY(BO17):_xlfn.ANCHORARRAY(BT17),_xleta.SUM)*_xlfn.ANCHORARRAY(O17))} -> 0 | M17: {=INT(_xlfn.BYROW(_xlfn.ANCHORARRAY(CA17):_xlfn.ANCHORARRAY(CF17),_xleta.SUM)*_xlfn.ANCHORARRAY(O17))} -> 0 | N17: {=INT(_xlfn.BYROW(_xlfn.ANCHORARRAY(CM17):_xlfn.ANCHORARRAY(CR17),_xleta.SUM)*_xlfn.ANCHORARRAY(O17))} -> 0 | O17: {=IF(_xlfn.XLOOKUP(_xlfn.ANCHORARRAY(P17),AtkParam!A:A,AtkParam!M:M)=I11,H11,1)} -> 1 | P17: {=IF(_xlfn.ANCHORARRAY($D$17)="是",_xlfn.XLOOKUP(_xlfn.ANCHORARRAY($A$17),SpellData!$A:$A,SpellData!P:P),_xlfn.XLOOKUP(_xlfn.ANCHORARRAY($A$17),SpellData!$A:$A,SpellData!J:J))} -> 40000 | Q17: {=IF(_xlfn.ANCHORARRAY($D$17)="是",_xlfn.XLOOKUP(_xlfn.ANCHORARRAY($A$17),SpellData!$A:$A,SpellData!Q:Q),_xlfn.XLOOKUP(_xlfn.ANCHORARRAY($A$17),SpellData!$A:$A,SpellData!K:K))} -> 0 | R17: {=IF(_xlfn.ANCHORARRAY($D$17)="是",_xlfn.XLOOKUP(_xlfn.ANCHORARRAY($A$17),SpellData!$A:$A,SpellData!R:R),_xlfn.XLOOKUP(_xlfn.ANCHORARRAY($A$17),SpellData!$A:$A,SpellData!L:L))} -> 0 | S17: {=IF(_xlfn.ANCHORARRAY($D$17)="是",_xlfn.XLOOKUP(_xlfn.ANCHORARRAY($A$17),SpellData!$A:$A,SpellData!S:S),_xlfn.XLOOKUP(_xlfn.ANCHORARRAY($A$17),SpellData!$A:$A,SpellData!M:M))} -> 0 | T17: {=IF(_xlfn.ANCHORARRAY($D$17)="是",_xlfn.XLOOKUP(_xlfn.ANCHORARRAY($A$17),SpellData!$A:$A,SpellData!T:T),_xlfn.XLOOKUP(_xlfn.ANCHORARRAY($A$17),SpellData!$A:$A,SpellData!N:N))} -> 0 | U17: {=IF(_xlfn.ANCHORARRAY($D$17)="是",_xlfn.XLOOKUP(_xlfn.ANCHORARRAY($A$17),SpellData!$A:$A,SpellData!U:U),_xlfn.XLOOKUP(_xlfn.ANCHORARRAY($A$17),SpellData!$A:$A,SpellData!O:O))} -> 0 | V17: {=_xlfn.XLOOKUP(_xlfn.ANCHORARRAY($A$17),SpellData!$A:$A,SpellData!G:G)} -> 0 | W17: {=_xlfn.XLOOKUP(_xlfn.ANCHORARRAY($A$17),SpellData!$A:$A,SpellData!H:H)} -> 0 | X17: {=_xlfn.XLOOKUP(_xlfn.ANCHORARRAY($A$17),SpellData!$A:$A,SpellData!I:I)} -> 0 | Y17: {=IF(_xlfn.ANCHORARRAY(P17)=0,,_xlfn.XLOOKUP(_xlfn.ANCHORARRAY(P17),AtkParam!$A:$A,AtkParam!$C:$C,0)+IF($E$11="是",IF(_xlfn.ANCHORARRAY(P17)=_xlfn.ANCHORARRAY($V$17),$F$11)+IF(_xlfn.ANCHORARRAY(P17)=_xlfn.ANCHORARRAY($W$17),$F$11)+IF(_xlfn.ANCHORARRAY(P17)=_xlfn.ANCHORARRAY($X$17),$F$11,),))} -> 1 | Z17: {=IF(_xlfn.ANCHORARRAY(Q17)=0,,_xlfn.XLOOKUP(_xlfn.ANCHORARRAY(Q17),AtkParam!$A:$A,AtkParam!$C:$C,0)+IF($E$11="是",IF(_xlfn.ANCHORARRAY(Q17)=_xlfn.ANCHORARRAY($V$17),$F$11)+IF(_xlfn.ANCHORARRAY(Q17)=_xlfn.ANCHORARRAY($W$17),$F$11)+IF(_xlfn.ANCHORARRAY(Q17)=_xlfn.ANCHORARRAY($X$17),$F$11,),))} -> 0 | AA17: {=IF(_xlfn.ANCHORARRAY(R17)=0,,_xlfn.XLOOKUP(_xlfn.ANCHORARRAY(R17),AtkParam!$A:$A,AtkParam!$C:$C,0)+IF($E$11="是",IF(_xlfn.ANCHORARRAY(R17)=_xlfn.ANCHORARRAY($V$17),$F$11)+IF(_xlfn.ANCHORARRAY(R17)=_xlfn.ANCHORARRAY($W$17),$F$11)+IF(_xlfn.ANCHORARRAY(R17)=_xlfn.ANCHORARRAY($X$17),$F$11,),))} -> 0 | AB17: {=IF(_xlfn.ANCHORARRAY(S17)=0,,_xlfn.XLOOKUP(_xlfn.ANCHORARRAY(S17),AtkParam!$A:$A,AtkParam!$C:$C,0)+IF($E$11="是",IF(_xlfn.ANCHORARRAY(S17)=_xlfn.ANCHORARRAY($V$17),$F$11)+IF(_xlfn.ANCHORARRAY(S17)=_xlfn.ANCHORARRAY($W$17),$F$11)+IF(_xlfn.ANCHORARRAY(S17)=_xlfn.ANCHORARRAY($X$17),$F$11,),))} -> 0 | AC17: {=IF(_xlfn.ANCHORARRAY(T17)=0,,_xlfn.XLOOKUP(_xlfn.ANCHORARRAY(T17),AtkParam!$A:$A,AtkParam!$C:$C,0)+IF($E$11="是",IF(_xlfn.ANCHORARRAY(T17)=_xlfn.ANCHORARRAY($V$17),$F$11)+IF(_xlfn.ANCHORARRAY(T17)=_xlfn.ANCHORARRAY($W$17),$F$11)+IF(_xlfn.ANCHORARRAY(T17)=_xlfn.ANCHORARRAY($X$17),$F$11,),))} -> 0 | AD17: {=IF(_xlfn.ANCHORARRAY(U17)=0,,_xlfn.XLOOKUP(_xlfn.ANCHORARRAY(U17),AtkParam!$A:$A,AtkParam!$C:$C,0)+IF($E$11="是",IF(_xlfn.ANCHORARRAY(U17)=_xlfn.ANCHORARRAY($V$17),$F$11)+IF(_xlfn.ANCHORARRAY(U17)=_xlfn.ANCHORARRAY($W$17),$F$11)+IF(_xlfn.ANCHORARRAY(U17)=_xlfn.ANCHORARRAY($X$17),$F$11,),))} -> 0 | AE17: {=_xlfn.XLOOKUP(_xlfn.ANCHORARRAY(P17),AtkParam!$A:$A,AtkParam!$L:$L,"无")} -> 无 | AF17: {=_xlfn.XLOOKUP(_xlfn.ANCHORARRAY(Q17),AtkParam!$A:$A,AtkParam!$L:$L,"无")} -> 无 | AG17: {=_xlfn.XLOOKUP(_xlfn.ANCHORARRAY(R17),AtkParam!$A:$A,AtkParam!$L:$L,"无")} -> 无 | AH17: {=_xlfn.XLOOKUP(_xlfn.ANCHORARRAY(S17),AtkParam!$A:$A,AtkParam!$L:$L,"无")} -> 无 | AI17: {=_xlfn.XLOOKUP(_xlfn.ANCHORARRAY(T17),AtkParam!$A:$A,AtkParam!$L:$L,"无")} -> 无 | AJ17: {=_xlfn.XLOOKUP(_xlfn.ANCHORARRAY(U17),AtkParam!$A:$A,AtkParam!$L:$L,"无")} -> 无 | AK17: {=_xlfn.XLOOKUP(_xlfn.ANCHORARRAY(P17),AtkParam!$A:$A,AtkParam!$G:$G,0)*$E$8%} -> 0 | AL17: {=_xlfn.XLOOKUP(_xlfn.ANCHORARRAY(Q17),AtkParam!$A:$A,AtkParam!$G:$G,0)*$E$8%} -> 0 | AM17: {=_xlfn.XLOOKUP(_xlfn.ANCHORARRAY(R17),AtkParam!$A:$A,AtkParam!$G:$G,0)*$E$8%} -> 0 | AN17: {=_xlfn.XLOOKUP(_xlfn.ANCHORARRAY(S17),AtkParam!$A:$A,AtkParam!$G:$G,0)*$E$8%} -> 0 | AO17: {=_xlfn.XLOOKUP(_xlfn.ANCHORARRAY(T17),AtkParam!$A:$A,AtkParam!$G:$G,0)*$E$8%} -> 0 | AP17: {=_xlfn.XLOOKUP(_xlfn.ANCHORARRAY(U17),AtkParam!$A:$A,AtkParam!$G:$G,0)*$E$8%} -> 0 | AQ17: {=_xlfn.LET(_xlpm.r,_xlfn.XLOOKUP(_xlfn.ANCHORARRAY(AE17),$B$12:$E$12,$B$14:$E$14,0),_xlpm.p,_xlfn.ANCHORARRAY(AK17)/$E$13,_xlpm.q,MATCH(_xlpm.p,List!$C$2:$C$6),_xlpm.a,INDEX(List!$D$2:$D$6,_xlpm.q),_xlpm.b,INDEX(List!$E$2:$E$6,_xlpm.q),_xlpm.c,INDEX(List!$F$2:$F$6,_xlpm.q),INT((_xlpm.a*(_xlpm.p-_xlpm.b)^2+_xlpm.c)*_xlfn.ANCHORARRAY(AK17)*_xlpm.r)*_xlfn.ANCHORARRAY(Y17))} -> 0 | AR17: {=_xlfn.LET(_xlpm.r,_xlfn.XLOOKUP(_xlfn.ANCHORARRAY(AF17),$B$12:$E$12,$B$14:$E$14,0),_xlpm.p,_xlfn.ANCHORARRAY(AL17)/$E$13,_xlpm.q,MATCH(_xlpm.p,List!$C$2:$C$6),_xlpm.a,INDEX(List!$D$2:$D$6,_xlpm.q),_xlpm.b,INDEX(List!$E$2:$E$6,_xlpm.q),_xlpm.c,INDEX(List!$F$2:$F$6,_xlpm.q),INT((_xlpm.a*(_xlpm.p-_xlpm.b)^2+_xlpm.c)*_xlfn.ANCHORARRAY(AL17)*_xlpm.r)*_xlfn.ANCHORARRAY(Z17))} -> 0 | AS17: {=_xlfn.LET(_xlpm.r,_xlfn.XLOOKUP(_xlfn.ANCHORARRAY(AG17),$B$12:$E$12,$B$14:$E$14,0),_xlpm.p,_xlfn.ANCHORARRAY(AM17)/$E$13,_xlpm.q,MATCH(_xlpm.p,List!$C$2:$C$6),_xlpm.a,INDEX(List!$D$2:$D$6,_xlpm.q),_xlpm.b,INDEX(List!$E$2:$E$6,_xlpm.q),_xlpm.c,INDEX(List!$F$2:$F$6,_xlpm.q),INT((_xlpm.a*(_xlpm.p-_xlpm.b)^2+_xlpm.c)*_xlfn.ANCHORARRAY(AM17)*_xlpm.r)*_xlfn.ANCHORARRAY(AA17))} -> 0 | AT17: {=_xlfn.LET(_xlpm.r,_xlfn.XLOOKUP(_xlfn.ANCHORARRAY(AH17),$B$12:$E$12,$B$14:$E$14,0),_xlpm.p,_xlfn.ANCHORARRAY(AN17)/$E$13,_xlpm.q,MATCH(_xlpm.p,List!$C$2:$C$6),_xlpm.a,INDEX(List!$D$2:$D$6,_xlpm.q),_xlpm.b,INDEX(List!$E$2:$E$6,_xlpm.q),_xlpm.c,INDEX(List!$F$2:$F$6,_xlpm.q),INT((_xlpm.a*(_xlpm.p-_xlpm.b)^2+_xlpm.c)*_xlfn.ANCHORARRAY(AN17)*_xlpm.r)*_xlfn.ANCHORARRAY(AB17))} -> 0 | AU17: {=_xlfn.LET(_xlpm.r,_xlfn.XLOOKUP(_xlfn.ANCHORARRAY(AI17),$B$12:$E$12,$B$14:$E$14,0),_xlpm.p,_xlfn.ANCHORARRAY(AO17)/$E$13,_xlpm.q,MATCH(_xlpm.p,List!$C$2:$C$6),_xlpm.a,INDEX(List!$D$2:$D$6,_xlpm.q),_xlpm.b,INDEX(List!$E$2:$E$6,_xlpm.q),_xlpm.c,INDEX(List!$F$2:$F$6,_xlpm.q),INT((_xlpm.a*(_xlpm.p-_xlpm.b)^2+_xlpm.c)*_xlfn.ANCHORARRAY(AO17)*_xlpm.r)*_xlfn.ANCHORARRAY(AC17))} -> 0 | AV17: {=_xlfn.LET(_xlpm.r,_xlfn.XLOOKUP(_xlfn.ANCHORARRAY(AJ17),$B$12:$E$12,$B$14:$E$14,0),_xlpm.p,_xlfn.ANCHORARRAY(AP17)/$E$13,_xlpm.q,MATCH(_xlpm.p,List!$C$2:$C$6),_xlpm.a,INDEX(List!$D$2:$D$6,_xlpm.q),_xlpm.b,INDEX(List!$E$2:$E$6,_xlpm.q),_xlpm.c,INDEX(List!$F$2:$F$6,_xlpm.q),INT((_xlpm.a*(_xlpm.p-_xlpm.b)^2+_xlpm.c)*_xlfn.ANCHORARRAY(AP17)*_xlpm.r)*_xlfn.ANCHORARRAY(AD17))} -> 0 | AW17: {=_xlfn.XLOOKUP(_xlfn.ANCHORARRAY(P17),AtkParam!$A:$A,AtkParam!$H:$H,0)*$F$8%} -> 653.6 | AX17: {=_xlfn.XLOOKUP(_xlfn.ANCHORARRAY(Q17),AtkParam!$A:$A,AtkParam!$H:$H,0)*$F$8%} -> 0 | AY17: {=_xlfn.XLOOKUP(_xlfn.ANCHORARRAY(R17),AtkParam!$A:$A,AtkParam!$H:$H,0)*$F$8%} -> 0 | AZ17: {=_xlfn.XLOOKUP(_xlfn.ANCHORARRAY(S17),AtkParam!$A:$A,AtkParam!$H:$H,0)*$F$8%} -> 0 | BA17: {=_xlfn.XLOOKUP(_xlfn.ANCHORARRAY(T17),AtkParam!$A:$A,AtkParam!$H:$H,0)*$F$8%} -> 0 | BB17: {=_xlfn.XLOOKUP(_xlfn.ANCHORARRAY(U17),AtkParam!$A:$A,AtkParam!$H:$H,0)*$F$8%} -> 0 | BC17: {=_xlfn.LET(_xlpm.r,$F$14,_xlpm.p,_xlfn.ANCHORARRAY(AW17)/$F$13,_xlpm.q,MATCH(_xlpm.p,List!$C$2:$C$6),_xlpm.a,INDEX(List!$D$2:$D$6,_xlpm.q),_xlpm.b,INDEX(List!$E$2:$E$6,_xlpm.q),_xlpm.c,INDEX(List!$F$2:$F$6,_xlpm.q),INT((_xlpm.a*(_xlpm.p-_xlpm.b)^2+_xlpm.c)*_xlfn.ANCHORARRAY(AW17)*_xlpm.r)*_xlfn.ANCHORARRAY(Y17))} -> 563 | BD17: {=_xlfn.LET(_xlpm.r,$F$14,_xlpm.p,_xlfn.ANCHORARRAY(AX17)/$F$13,_xlpm.q,MATCH(_xlpm.p,List!$C$2:$C$6),_xlpm.a,INDEX(List!$D$2:$D$6,_xlpm.q),_xlpm.b,INDEX(List!$E$2:$E$6,_xlpm.q),_xlpm.c,INDEX(List!$F$2:$F$6,_xlpm.q),INT((_xlpm.a*(_xlpm.p-_xlpm.b)^2+_xlpm.c)*_xlfn.ANCHORARRAY(AX17)*_xlpm.r)*_xlfn.ANCHORARRAY(Z17))} -> 0 | BE17: {=_xlfn.LET(_xlpm.r,$F$14,_xlpm.p,_xlfn.ANCHORARRAY(AY17)/$F$13,_xlpm.q,MATCH(_xlpm.p,List!$C$2:$C$6),_xlpm.a,INDEX(List!$D$2:$D$6,_xlpm.q),_xlpm.b,INDEX(List!$E$2:$E$6,_xlpm.q),_xlpm.c,INDEX(List!$F$2:$F$6,_xlpm.q),INT((_xlpm.a*(_xlpm.p-_xlpm.b)^2+_xlpm.c)*_xlfn.ANCHORARRAY(AY17)*_xlpm.r)*_xlfn.ANCHORARRAY(AA17))} -> 0 | BF17: {=_xlfn.LET(_xlpm.r,$F$14,_xlpm.p,_xlfn.ANCHORARRAY(AZ17)/$F$13,_xlpm.q,MATCH(_xlpm.p,List!$C$2:$C$6),_xlpm.a,INDEX(List!$D$2:$D$6,_xlpm.q),_xlpm.b,INDEX(List!$E$2:$E$6,_xlpm.q),_xlpm.c,INDEX(List!$F$2:$F$6,_xlpm.q),INT((_xlpm.a*(_xlpm.p-_xlpm.b)^2+_xlpm.c)*_xlfn.ANCHORARRAY(AZ17)*_xlpm.r)*_xlfn.ANCHORARRAY(AB17))} -> 0 | BG17: {=_xlfn.LET(_xlpm.r,$F$14,_xlpm.p,_xlfn.ANCHORARRAY(BA17)/$F$13,_xlpm.q,MATCH(_xlpm.p,List!$C$2:$C$6),_xlpm.a,INDEX(List!$D$2:$D$6,_xlpm.q),_xlpm.b,INDEX(List!$E$2:$E$6,_xlpm.q),_xlpm.c,INDEX(List!$F$2:$F$6,_xlpm.q),INT((_xlpm.a*(_xlpm.p-_xlpm.b)^2+_xlpm.c)*_xlfn.ANCHORARRAY(BA17)*_xlpm.r)*_xlfn.ANCHORARRAY(AC17))} -> 0 | BH17: {=_xlfn.LET(_xlpm.r,$F$14,_xlpm.p,_xlfn.ANCHORARRAY(BB17)/$F$13,_xlpm.q,MATCH(_xlpm.p,List!$C$2:$C$6),_xlpm.a,INDEX(List!$D$2:$D$6,_xlpm.q),_xlpm.b,INDEX(List!$E$2:$E$6,_xlpm.q),_xlpm.c,INDEX(List!$F$2:$F$6,_xlpm.q),INT((_xlpm.a*(_xlpm.p-_xlpm.b)^2+_xlpm.c)*_xlfn.ANCHORARRAY(BB17)*_xlpm.r)*_xlfn.ANCHORARRAY(AD17))} -> 0 | BI17: {=_xlfn.XLOOKUP(_xlfn.ANCHORARRAY(P17),AtkParam!$A:$A,AtkParam!$I:$I,0)*$G$8%} -> 0 | BJ17: {=_xlfn.XLOOKUP(_xlfn.ANCHORARRAY(Q17),AtkParam!$A:$A,AtkParam!$I:$I,0)*$G$8%} -> 0 | BK17: {=_xlfn.XLOOKUP(_xlfn.ANCHORARRAY(R17),AtkParam!$A:$A,AtkParam!$I:$I,0)*$G$8%} -> 0 | BL17: {=_xlfn.XLOOKUP(_xlfn.ANCHORARRAY(S17),AtkParam!$A:$A,AtkParam!$I:$I,0)*$G$8%} -> 0 | BM17: {=_xlfn.XLOOKUP(_xlfn.ANCHORARRAY(T17),AtkParam!$A:$A,AtkParam!$I:$I,0)*$G$8%} -> 0 | BN17: {=_xlfn.XLOOKUP(_xlfn.ANCHORARRAY(U17),AtkParam!$A:$A,AtkParam!$I:$I,0)*$G$8%} -> 0 | BO17: {=_xlfn.LET(_xlpm.r,$G$14,_xlpm.p,_xlfn.ANCHORARRAY(BI17)/$G$13,_xlpm.q,MATCH(_xlpm.p,List!$C$2:$C$6),_xlpm.a,INDEX(List!$D$2:$D$6,_xlpm.q),_xlpm.b,INDEX(List!$E$2:$E$6,_xlpm.q),_xlpm.c,INDEX(List!$F$2:$F$6,_xlpm.q),INT((_xlpm.a*(_xlpm.p-_xlpm.b)^2+_xlpm.c)*_xlfn.ANCHORARRAY(BI17)*_xlpm.r)*_xlfn.ANCHORARRAY(Y17))} -> 0 | BP17: {=_xlfn.LET(_xlpm.r,$G$14,_xlpm.p,_xlfn.ANCHORARRAY(BJ17)/$G$13,_xlpm.q,MATCH(_xlpm.p,List!$C$2:$C$6),_xlpm.a,INDEX(List!$D$2:$D$6,_xlpm.q),_xlpm.b,INDEX(List!$E$2:$E$6,_xlpm.q),_xlpm.c,INDEX(List!$F$2:$F$6,_xlpm.q),INT((_xlpm.a*(_xlpm.p-_xlpm.b)^2+_xlpm.c)*_xlfn.ANCHORARRAY(BJ17)*_xlpm.r)*_xlfn.ANCHORARRAY(Z17))} -> 0 | BQ17: {=_xlfn.LET(_xlpm.r,$G$14,_xlpm.p,_xlfn.ANCHORARRAY(BK17)/$G$13,_xlpm.q,MATCH(_xlpm.p,List!$C$2:$C$6),_xlpm.a,INDEX(List!$D$2:$D$6,_xlpm.q),_xlpm.b,INDEX(List!$E$2:$E$6,_xlpm.q),_xlpm.c,INDEX(List!$F$2:$F$6,_xlpm.q),INT((_xlpm.a*(_xlpm.p-_xlpm.b)^2+_xlpm.c)*_xlfn.ANCHORARRAY(BK17)*_xlpm.r)*_xlfn.ANCHORARRAY(AA17))} -> 0 | BR17: {=_xlfn.LET(_xlpm.r,$G$14,_xlpm.p,_xlfn.ANCHORARRAY(BL17)/$G$13,_xlpm.q,MATCH(_xlpm.p,List!$C$2:$C$6),_xlpm.a,INDEX(List!$D$2:$D$6,_xlpm.q),_xlpm.b,INDEX(List!$E$2:$E$6,_xlpm.q),_xlpm.c,INDEX(List!$F$2:$F$6,_xlpm.q),INT((_xlpm.a*(_xlpm.p-_xlpm.b)^2+_xlpm.c)*_xlfn.ANCHORARRAY(BL17)*_xlpm.r)*_xlfn.ANCHORARRAY(AB17))} -> 0 | BS17: {=_xlfn.LET(_xlpm.r,$G$14,_xlpm.p,_xlfn.ANCHORARRAY(BM17)/$G$13,_xlpm.q,MATCH(_xlpm.p,List!$C$2:$C$6),_xlpm.a,INDEX(List!$D$2:$D$6,_xlpm.q),_xlpm.b,INDEX(List!$E$2:$E$6,_xlpm.q),_xlpm.c,INDEX(List!$F$2:$F$6,_xlpm.q),INT((_xlpm.a*(_xlpm.p-_xlpm.b)^2+_xlpm.c)*_xlfn.ANCHORARRAY(BM17)*_xlpm.r)*_xlfn.ANCHORARRAY(AC17))} -> 0 | BT17: {=_xlfn.LET(_xlpm.r,$G$14,_xlpm.p,_xlfn.ANCHORARRAY(BN17)/$G$13,_xlpm.q,MATCH(_xlpm.p,List!$C$2:$C$6),_xlpm.a,INDEX(List!$D$2:$D$6,_xlpm.q),_xlpm.b,INDEX(List!$E$2:$E$6,_xlpm.q),_xlpm.c,INDEX(List!$F$2:$F$6,_xlpm.q),INT((_xlpm.a*(_xlpm.p-_xlpm.b)^2+_xlpm.c)*_xlfn.ANCHORARRAY(BN17)*_xlpm.r)*_xlfn.ANCHORARRAY(AD17))} -> 0 | BU17: {=_xlfn.XLOOKUP(_xlfn.ANCHORARRAY(P17),AtkParam!$A:$A,AtkParam!$J:$J,0)*$H$8%} -> 0 | BV17: {=_xlfn.XLOOKUP(_xlfn.ANCHORARRAY(Q17),AtkParam!$A:$A,AtkParam!$J:$J,0)*$H$8%} -> 0 | BW17: {=_xlfn.XLOOKUP(_xlfn.ANCHORARRAY(R17),AtkParam!$A:$A,AtkParam!$J:$J,0)*$H$8%} -> 0 | BX17: {=_xlfn.XLOOKUP(_xlfn.ANCHORARRAY(S17),AtkParam!$A:$A,AtkParam!$J:$J,0)*$H$8%} -> 0 | BY17: {=_xlfn.XLOOKUP(_xlfn.ANCHORARRAY(T17),AtkParam!$A:$A,AtkParam!$J:$J,0)*$H$8%} -> 0 | BZ17: {=_xlfn.XLOOKUP(_xlfn.ANCHORARRAY(U17),AtkParam!$A:$A,AtkParam!$J:$J,0)*$H$8%} -> 0 | CA17: {=_xlfn.LET(_xlpm.r,$H$14,_xlpm.p,_xlfn.ANCHORARRAY(BU17)/$H$13,_xlpm.q,MATCH(_xlpm.p,List!$C$2:$C$6),_xlpm.a,INDEX(List!$D$2:$D$6,_xlpm.q),_xlpm.b,INDEX(List!$E$2:$E$6,_xlpm.q),_xlpm.c,INDEX(List!$F$2:$F$6,_xlpm.q),INT((_xlpm.a*(_xlpm.p-_xlpm.b)^2+_xlpm.c)*_xlfn.ANCHORARRAY(BU17)*_xlpm.r)*_xlfn.ANCHORARRAY(Y17))} -> 0 | CB17: {=_xlfn.LET(_xlpm.r,$H$14,_xlpm.p,_xlfn.ANCHORARRAY(BV17)/$H$13,_xlpm.q,MATCH(_xlpm.p,List!$C$2:$C$6),_xlpm.a,INDEX(List!$D$2:$D$6,_xlpm.q),_xlpm.b,INDEX(List!$E$2:$E$6,_xlpm.q),_xlpm.c,INDEX(List!$F$2:$F$6,_xlpm.q),INT((_xlpm.a*(_xlpm.p-_xlpm.b)^2+_xlpm.c)*_xlfn.ANCHORARRAY(BV17)*_xlpm.r)*_xlfn.ANCHORARRAY(Z17))} -> 0 | CC17: {=_xlfn.LET(_xlpm.r,$H$14,_xlpm.p,_xlfn.ANCHORARRAY(BW17)/$H$13,_xlpm.q,MATCH(_xlpm.p,List!$C$2:$C$6),_xlpm.a,INDEX(List!$D$2:$D$6,_xlpm.q),_xlpm.b,INDEX(List!$E$2:$E$6,_xlpm.q),_xlpm.c,INDEX(List!$F$2:$F$6,_xlpm.q),INT((_xlpm.a*(_xlpm.p-_xlpm.b)^2+_xlpm.c)*_xlfn.ANCHORARRAY(BW17)*_xlpm.r)*_xlfn.ANCHORARRAY(AA17))} -> 0 | CD17: {=_xlfn.LET(_xlpm.r,$H$14,_xlpm.p,_xlfn.ANCHORARRAY(BX17)/$H$13,_xlpm.q,MATCH(_xlpm.p,List!$C$2:$C$6),_xlpm.a,INDEX(List!$D$2:$D$6,_xlpm.q),_xlpm.b,INDEX(List!$E$2:$E$6,_xlpm.q),_xlpm.c,INDEX(List!$F$2:$F$6,_xlpm.q),INT((_xlpm.a*(_xlpm.p-_xlpm.b)^2+_xlpm.c)*_xlfn.ANCHORARRAY(BX17)*_xlpm.r)*_xlfn.ANCHORARRAY(AB17))} -> 0 | CE17: {=_xlfn.LET(_xlpm.r,$H$14,_xlpm.p,_xlfn.ANCHORARRAY(BY17)/$H$13,_xlpm.q,MATCH(_xlpm.p,List!$C$2:$C$6),_xlpm.a,INDEX(List!$D$2:$D$6,_xlpm.q),_xlpm.b,INDEX(List!$E$2:$E$6,_xlpm.q),_xlpm.c,INDEX(List!$F$2:$F$6,_xlpm.q),INT((_xlpm.a*(_xlpm.p-_xlpm.b)^2+_xlpm.c)*_xlfn.ANCHORARRAY(BY17)*_xlpm.r)*_xlfn.ANCHORARRAY(AC17))} -> 0 | CF17: {=_xlfn.LET(_xlpm.r,$H$14,_xlpm.p,_xlfn.ANCHORARRAY(BZ17)/$H$13,_xlpm.q,MATCH(_xlpm.p,List!$C$2:$C$6),_xlpm.a,INDEX(List!$D$2:$D$6,_xlpm.q),_xlpm.b,INDEX(List!$E$2:$E$6,_xlpm.q),_xlpm.c,INDEX(List!$F$2:$F$6,_xlpm.q),INT((_xlpm.a*(_xlpm.p-_xlpm.b)^2+_xlpm.c)*_xlfn.ANCHORARRAY(BZ17)*_xlpm.r)*_xlfn.ANCHORARRAY(AD17))} -> 0 | CG17: {=_xlfn.XLOOKUP(_xlfn.ANCHORARRAY(P17),AtkParam!$A:$A,AtkParam!$K:$K,0)*$I$8%} -> 0 | CH17: {=_xlfn.XLOOKUP(_xlfn.ANCHORARRAY(Q17),AtkParam!$A:$A,AtkParam!$K:$K,0)*$I$8%} -> 0 | CI17: {=_xlfn.XLOOKUP(_xlfn.ANCHORARRAY(R17),AtkParam!$A:$A,AtkParam!$K:$K,0)*$I$8%} -> 0 | CJ17: {=_xlfn.XLOOKUP(_xlfn.ANCHORARRAY(S17),AtkParam!$A:$A,AtkParam!$K:$K,0)*$I$8%} -> 0 | CK17: {=_xlfn.XLOOKUP(_xlfn.ANCHORARRAY(T17),AtkParam!$A:$A,AtkParam!$K:$K,0)*$I$8%} -> 0 | CL17: {=_xlfn.XLOOKUP(_xlfn.ANCHORARRAY(U17),AtkParam!$A:$A,AtkParam!$K:$K,0)*$I$8%} -> 0 | CM17: {=_xlfn.LET(_xlpm.r,$I$14,_xlpm.p,_xlfn.ANCHORARRAY(CG17)/$I$13,_xlpm.q,MATCH(_xlpm.p,List!$C$2:$C$6),_xlpm.a,INDEX(List!$D$2:$D$6,_xlpm.q),_xlpm.b,INDEX(List!$E$2:$E$6,_xlpm.q),_xlpm.c,INDEX(List!$F$2:$F$6,_xlpm.q),INT((_xlpm.a*(_xlpm.p-_xlpm.b)^2+_xlpm.c)*_xlfn.ANCHORARRAY(CG17)*_xlpm.r)*_xlfn.ANCHORARRAY(Y17))} -> 0 | CN17: {=_xlfn.LET(_xlpm.r,$I$14,_xlpm.p,_xlfn.ANCHORARRAY(CH17)/$I$13,_xlpm.q,MATCH(_xlpm.p,List!$C$2:$C$6),_xlpm.a,INDEX(List!$D$2:$D$6,_xlpm.q),_xlpm.b,INDEX(List!$E$2:$E$6,_xlpm.q),_xlpm.c,INDEX(List!$F$2:$F$6,_xlpm.q),INT((_xlpm.a*(_xlpm.p-_xlpm.b)^2+_xlpm.c)*_xlfn.ANCHORARRAY(CH17)*_xlpm.r)*_xlfn.ANCHORARRAY(Z17))} -> 0 | CO17: {=_xlfn.LET(_xlpm.r,$I$14,_xlpm.p,_xlfn.ANCHORARRAY(CI17)/$I$13,_xlpm.q,MATCH(_xlpm.p,List!$C$2:$C$6),_xlpm.a,INDEX(List!$D$2:$D$6,_xlpm.q),_xlpm.b,INDEX(List!$E$2:$E$6,_xlpm.q),_xlpm.c,INDEX(List!$F$2:$F$6,_xlpm.q),INT((_xlpm.a*(_xlpm.p-_xlpm.b)^2+_xlpm.c)*_xlfn.ANCHORARRAY(CI17)*_xlpm.r)*_xlfn.ANCHORARRAY(AA17))} -> 0 | CP17: {=_xlfn.LET(_xlpm.r,$I$14,_xlpm.p,_xlfn.ANCHORARRAY(CJ17)/$I$13,_xlpm.q,MATCH(_xlpm.p,List!$C$2:$C$6),_xlpm.a,INDEX(List!$D$2:$D$6,_xlpm.q),_xlpm.b,INDEX(List!$E$2:$E$6,_xlpm.q),_xlpm.c,INDEX(List!$F$2:$F$6,_xlpm.q),INT((_xlpm.a*(_xlpm.p-_xlpm.b)^2+_xlpm.c)*_xlfn.ANCHORARRAY(CJ17)*_xlpm.r)*_xlfn.ANCHORARRAY(AB17))} -> 0 | CQ17: {=_xlfn.LET(_xlpm.r,$I$14,_xlpm.p,_xlfn.ANCHORARRAY(CK17)/$I$13,_xlpm.q,MATCH(_xlpm.p,List!$C$2:$C$6),_xlpm.a,INDEX(List!$D$2:$D$6,_xlpm.q),_xlpm.b,INDEX(List!$E$2:$E$6,_xlpm.q),_xlpm.c,INDEX(List!$F$2:$F$6,_xlpm.q),INT((_xlpm.a*(_xlpm.p-_xlpm.b)^2+_xlpm.c)*_xlfn.ANCHORARRAY(CK17)*_xlpm.r)*_xlfn.ANCHORARRAY(AC17))} -> 0 | CR17: {=_xlfn.LET(_xlpm.r,$I$14,_xlpm.p,_xlfn.ANCHORARRAY(CL17)/$I$13,_xlpm.q,MATCH(_xlpm.p,List!$C$2:$C$6),_xlpm.a,INDEX(List!$D$2:$D$6,_xlpm.q),_xlpm.b,INDEX(List!$E$2:$E$6,_xlpm.q),_xlpm.c,INDEX(List!$F$2:$F$6,_xlpm.q),(_xlpm.a*(_xlpm.p-_xlpm.b)^2+_xlpm.c)*_xlfn.ANCHORARRAY(CL17)*_xlpm.r*_xlfn.ANCHORARRAY(AD17))} -> 0 | CS17: {=_xlfn.XLOOKUP(_xlfn.ANCHORARRAY(P17),AtkParam!$A:$A,AtkParam!$R:$R,0)} -> 3 | CT17: {=_xlfn.XLOOKUP(_xlfn.ANCHORARRAY(Q17),AtkParam!$A:$A,AtkParam!$R:$R,0)} -> 0 | CU17: {=_xlfn.XLOOKUP(_xlfn.ANCHORARRAY(R17),AtkParam!$A:$A,AtkParam!$R:$R,0)} -> 0 | CV17: {=_xlfn.XLOOKUP(_xlfn.ANCHORARRAY(S17),AtkParam!$A:$A,AtkParam!$R:$R,0)} -> 0 | CW17: {=_xlfn.XLOOKUP(_xlfn.ANCHORARRAY(T17),AtkParam!$A:$A,AtkParam!$R:$R,0)} -> 0 | CX17: {=_xlfn.XLOOKUP(_xlfn.ANCHORARRAY(U17),AtkParam!$A:$A,AtkParam!$R:$R,0)} -> 0 | CY17: {=_xlfn.XLOOKUP(_xlfn.ANCHORARRAY(P17),AtkParam!$A:$A,AtkParam!$S:$S,"")} -> 1 | CZ17: {=_xlfn.XLOOKUP(_xlfn.ANCHORARRAY(Q17),AtkParam!$A:$A,AtkParam!$S:$S,"")} | DA17: {=_xlfn.XLOOKUP(_xlfn.ANCHORARRAY(R17),AtkParam!$A:$A,AtkParam!$S:$S,"")} | DB17: {=_xlfn.XLOOKUP(_xlfn.ANCHORARRAY(S17),AtkParam!$A:$A,AtkParam!$S:$S,"")} | DC17: {=_xlfn.XLOOKUP(_xlfn.ANCHORARRAY(T17),AtkParam!$A:$A,AtkParam!$S:$S,"")} | DD17: {=_xlfn.XLOOKUP(_xlfn.ANCHORARRAY(U17),AtkParam!$A:$A,AtkParam!$S:$S,"")} | DE17: {=_xlfn.XLOOKUP(_xlfn.ANCHORARRAY(P17),AtkParam!$A:$A,AtkParam!$T:$T,0)} -> 0 | DF17: {=_xlfn.XLOOKUP(_xlfn.ANCHORARRAY(Q17),AtkParam!$A:$A,AtkParam!$T:$T,0)} -> 0 | DG17: {=_xlfn.XLOOKUP(_xlfn.ANCHORARRAY(R17),AtkParam!$A:$A,AtkParam!$T:$T,0)} -> 0 | DH17: {=_xlfn.XLOOKUP(_xlfn.ANCHORARRAY(S17),AtkParam!$A:$A,AtkParam!$T:$T,0)} -> 0 | DI17: {=_xlfn.XLOOKUP(_xlfn.ANCHORARRAY(T17),AtkParam!$A:$A,AtkParam!$T:$T,0)} -> 0 | DJ17: {=_xlfn.XLOOKUP(_xlfn.ANCHORARRAY(U17),AtkParam!$A:$A,AtkParam!$T:$T,0)} -> 0 | DK17: {=_xlfn.BYROW(_xlfn.XLOOKUP(_xlfn.ANCHORARRAY(P17):_xlfn.ANCHORARRAY(U17),AtkParam!A:A,AtkParam!U:U,""),_xlfn.LAMBDA(_xlpm.x,_xlfn.CONCAT(_xlfn.UNIQUE(_xlpm.x,1))))} | DL17: {=_xlfn.BYROW(_xlfn.XLOOKUP(_xlfn.ANCHORARRAY(P17):_xlfn.ANCHORARRAY(U17),AtkParam!A:A,AtkParam!W:W,0)*_xlfn.ANCHORARRAY(Y17):_xlfn.ANCHORARRAY(AD17),_xleta.SUM)} -> 0
